Workbook

Sheet Specs
B1: CHATGPT | C1: CLAUDE | D1: DEEPSEEK | E1: GEMINI | F1: DATE CREATED
A2: pi-digits | B2: GPT 5.2 | C2: Sonnet 4.5 | D2: DeepSeek v3.2 | E2: Gemini 3.1 Pro | F2: 25/01/2026
A3: n-body | F3: 26/01/2026
A4: reverse-complement | F4: 25/01/2026
A5: fasta | F5: 23/01/2026
A6: k-nucleotide | F6: 25/01/2026
A7: regex-redux | F7: 25/01/2026
A8: spectral-norm | F8: 25/01/2026
A9: mandelbrot | F9: 26/01/2026
A10: binary-trees | F10: 26/01/2026
A11: fannkuch-redux | F11: 27/01/2026
E12: 29/07/2026

Sheet all-data
A1: BENCHMARK | B1: PROMPT | C1: SEARCH TYPE | D1: AI TOOL | E1: P. L. | F1: OPTIMAL LIBRARIES? | G1: OUTPUT COMMENT
A2: Fasta | B2: P1 | C2: Normal | D2: ChatGPT | E2: Python | F2: No. | G2: It worked.
A3: Fasta | B3: P1 | C3: TBR | D3: ChatGPT | E3: Python | F3: No. | G3: It worked. | I3: Count of OPTIMAL LIBRARIES? | J3: OPTIMAL LIBRARIES?
A4: Fasta | B4: P2 | C4: Normal | D4: ChatGPT | E4: Go | F4: No. | G4: It worked. | I4: PROMPT | J4: No. | K4: Not Applicable. | L4: Yes. | M4: Grand Total
A5: Fasta | B5: P2 | C5: TBR | D5: ChatGPT | E5: Rust | F5: No. | G5: It worked. | I5: P1 | J5: 90 | K5: 5 | L5: 14 | M5: 109
A6: Fasta | B6: P3 | C6: Normal | D6: ChatGPT | E6: Go | F6: No. | G6: It worked. | I6: P2 | J6: 81 | K6: 5 | L6: 5 | M6: 91
A7: Fasta | B7: P3 | C7: TBR | D7: ChatGPT | E7: Rust | F7: No. | G7: Compiled ok. Wrong output. | I7: P3 | J7: 95 | K7: 3 | L7: 8 | M7: 106
A8: Fasta | B8: P4 | C8: Normal | D8: ChatGPT | E8: Go | F8: No. | G8: It worked. | I8: P4 | J8: 93 | K8: 2 | L8: 8 | M8: 103
A9: Fasta | B9: P4 | C9: TBR | D9: ChatGPT | E9: Go | F9: No. | G9: It worked. | I9: Grand Total | J9: 359 | K9: 15 | L9: 35 | M9: 409
A10: Fasta | B10: P1 | C10: Normal | D10: Claude | E10: Python | F10: No. | G10: It worked.
A11: Fasta | B11: P1 | C11: TBR | D11: Claude | E11: Python | F11: No. | G11: It worked.
A12: Fasta | B12: P2 | C12: Normal | D12: Claude | E12: C | F12: No. | G12: It worked.
A13: Fasta | B13: P2 | C13: TBR | D13: Claude | E13: Python | F13: No. | G13: It worked.
A14: Fasta | B14: P3 | C14: Normal | D14: Claude | E14: Python | F14: No. | G14: It worked.
A15: Fasta | B15: P3 | C15: TBR | D15: Claude | E15: Python | F15: No. | G15: It worked.
A16: Fasta | B16: P4 | C16: Normal | D16: Claude | E16: Python | F16: No. | G16: It worked.
A17: Fasta | B17: P4 | C17: TBR | D17: Claude | E17: C | F17: No. | G17: It worked.
A18: Fasta | B18: P1 | C18: Normal | D18: DeepSeek | E18: Python | F18: Yes. | G18: It worked.
A19: Fasta | B19: P1 | C19: TBR | D19: DeepSeek | E19: Python | F19: No. | G19: It worked.
A20: Fasta | B20: P2 | C20: Normal | D20: DeepSeek | E20: Python | F20: No. | G20: It worked.
A21: Fasta | B21: P2 | C21: TBR | D21: DeepSeek | E21: Python | F21: No. | G21: Compiled ok. Wrong output.
... A410: Spectral-norm | B410: P4 | C410: TBR | D410: Gemini | E410: Go | F410: No. | G410: It worked.

Sheet all-data_locked
A1: BENCHMARK | B1: PROMPT | C1: SEARCH TYPE | D1: AI TOOL | E1: P. L. | F1: OUTPUT COMMENT
A2: Fasta | B2: P1 | C2: Normal | D2: ChatGPT | E2: Python | F2: It worked. | H2: ChatGPT | O2: Password: changeisnotrequired
A3: Fasta | B3: P1 | C3: Normal | D3: Claude | E3: Python | F3: It worked. | H3: Stage | I3: Success | J3: Total | K3: % | L3: ic95_lo | M3: ic95_hi
A4: Fasta | B4: P1 | C4: Normal | D4: DeepSeek | E4: Python | F4: It worked. | H4: P(G=1) | I4: =COUNTIFS($D$2:$D$410,"ChatGPT",$F$2:$F$410,"<>No Code") -> 65 | J4: =COUNTIF($D$2:$D$410,"ChatGPT") -> 80 | K4: =I4/J4 -> 0.8125 | L4: =(K4+1.96^2/(2*J4)-1.96*SQRT(K4*(1-K4)/J4+1.96^2/(4*J4^2)))/(1+1.96^2/J4) -> 0.71341474 | M4: =(K4+1.96^2/(2*J4)+1.96*SQRT(K4*(1-K4)/J4+1.96^2/(4*J4^2)))/(1+1.96^2/J4) -> 0.88294792
A5: Fasta | B5: P1 | C5: Normal | D5: Gemini | E5: Python | F5: It worked. | H5: P(R=1|G=1) | I5: =COUNTIFS($D$2:$D$410,"ChatGPT",$F$2:$F$410,"<>No Code",$F$2:$F$410,"<>It did not compile.") -> 62 | J5: =I4 -> 65 | K5: =I5/J5 -> 0.95384615 | L5: =(K5+1.96^2/(2*J5)-1.96*SQRT(K5*(1-K5)/J5+1.96^2/(4*J5^2)))/(1+1.96^2/J5) -> 0.87285948 | M5: =(K5+1.96^2/(2*J5)+1.96*SQRT(K5*(1-K5)/J5+1.96^2/(4*J5^2)))/(1+1.96^2/J5) -> 0.98418045
A6: Fasta | B6: P1 | C6: TBR | D6: ChatGPT | E6: Python | F6: It worked. | H6: P(C=1|R=1) | I6: =COUNTIFS($D$2:$D$410,"ChatGPT",$F$2:$F$410,"It worked.") -> 45 | J6: =I5 -> 62 | K6: =I6/J6 -> 0.72580645 | L6: =(K6+1.96^2/(2*J6)-1.96*SQRT(K6*(1-K6)/J6+1.96^2/(4*J6^2)))/(1+1.96^2/J6) -> 0.60407224 | M6: =(K6+1.96^2/(2*J6)+1.96*SQRT(K6*(1-K6)/J6+1.96^2/(4*J6^2)))/(1+1.96^2/J6) -> 0.82119081
A7: Fasta | B7: P1 | C7: TBR | D7: Claude | E7: Python | F7: It worked.
A8: Fasta | B8: P1 | C8: TBR | D8: DeepSeek | E8: Python | F8: It worked. | H8: Claude
A9: Fasta | B9: P1 | C9: TBR | D9: Gemini | E9: Python | F9: It worked. | H9: Stage | I9: Success | J9: Total | K9: % | L9: ic95_lo | M9: ic95_hi
A10: Fasta | B10: P2 | C10: Normal | D10: ChatGPT | E10: Go | F10: It worked. | H10: P(G=1) | I10: =COUNTIFS($D$2:$D$410,"Claude",$F$2:$F$410,"<>No Code") -> 115 | J10: =COUNTIF($D$2:$D$410,"Claude") -> 115 | K10: =I10/J10 -> 1 | L10: =(K10+1.96^2/(2*J10)-1.96*SQRT(K10*(1-K10)/J10+1.96^2/(4*J10^2)))/(1+1.96^2/J10) -> 0.96767462 | M10: =(K10+1.96^2/(2*J10)+1.96*SQRT(K10*(1-K10)/J10+1.96^2/(4*J10^2)))/(1+1.96^2/J10) -> 1
A11: Fasta | B11: P2 | C11: Normal | D11: Claude | E11: C | F11: It worked. | H11: P(R=1|G=1) | I11: =COUNTIFS($D$2:$D$410,"Claude",$F$2:$F$410,"<>No Code",$F$2:$F$410,"<>It did not compile.") -> 111 | J11: =I10 -> 115 | K11: =I11/J11 -> 0.96521739 | L11: =(K11+1.96^2/(2*J11)-1.96*SQRT(K11*(1-K11)/J11+1.96^2/(4*J11^2)))/(1+1.96^2/J11) -> 0.91396575 | M11: =(K11+1.96^2/(2*J11)+1.96*SQRT(K11*(1-K11)/J11+1.96^2/(4*J11^2)))/(1+1.96^2/J11) -> 0.98639238
A12: Fasta | B12: P2 | C12: Normal | D12: DeepSeek | E12: Python | F12: It worked. | H12: P(C=1|R=1) | I12: =COUNTIFS($D$2:$D$410,"Claude",$F$2:$F$410,"It worked.") -> 74 | J12: =I11 -> 111 | K12: =I12/J12 -> 0.66666667 | L12: =(K12+1.96^2/(2*J12)-1.96*SQRT(K12*(1-K12)/J12+1.96^2/(4*J12^2)))/(1+1.96^2/J12) -> 0.57469293 | M12: =(K12+1.96^2/(2*J12)+1.96*SQRT(K12*(1-K12)/J12+1.96^2/(4*J12^2)))/(1+1.96^2/J12) -> 0.74748997
A13: Fasta | B13: P2 | C13: Normal | D13: Gemini | E13: Go | F13: It did not compile.
A14: Fasta | B14: P2 | C14: TBR | D14: ChatGPT | E14: Rust | F14: It worked. | H14: DeepSeek
A15: Fasta | B15: P2 | C15: TBR | D15: Claude | E15: Python | F15: It worked. | H15: Stage | I15: Success | J15: Total | K15: % | L15: ic95_lo | M15: ic95_hi
A16: Fasta | B16: P2 | C16: TBR | D16: DeepSeek | E16: Python | F16: Compiled ok. Wrong output. | H16: P(G=1) | I16: =COUNTIFS($D$2:$D$410,"DeepSeek",$F$2:$F$410,"<>No Code") -> 132 | J16: =COUNTIF($D$2:$D$410,"DeepSeek") -> 132 | K16: =I16/J16 -> 1 | L16: =(K16+1.96^2/(2*J16)-1.96*SQRT(K16*(1-K16)/J16+1.96^2/(4*J16^2)))/(1+1.96^2/J16) -> 0.97172 | M16: =(K16+1.96^2/(2*J16)+1.96*SQRT(K16*(1-K16)/J16+1.96^2/(4*J16^2)))/(1+1.96^2/J16) -> 1
A17: Fasta | B17: P2 | C17: TBR | D17: Gemini | E17: Python | F17: It worked. | H17: P(R=1|G=1) | I17: =COUNTIFS($D$2:$D$410,"DeepSeek",$F$2:$F$410,"<>No Code",$F$2:$F$410,"<>It did not compile.") -> 112 | J17: =I16 -> 132 | K17: =I17/J17 -> 0.84848485 | L17: =(K17+1.96^2/(2*J17)-1.96*SQRT(K17*(1-K17)/J17+1.96^2/(4*J17^2)))/(1+1.96^2/J17) -> 0.77753344 | M17: =(K17+1.96^2/(2*J17)+1.96*SQRT(K17*(1-K17)/J17+1.96^2/(4*J17^2)))/(1+1.96^2/J17) -> 0.89972595
A18: Fasta | B18: P3 | C18: Normal | D18: ChatGPT | E18: Go | F18: It worked. | H18: P(C=1|R=1) | I18: =COUNTIFS($D$2:$D$410,"DeepSeek",$F$2:$F$410,"It worked.") -> 38 | J18: =I17 -> 112 | K18: =I18/J18 -> 0.33928571 | L18: =(K18+1.96^2/(2*J18)-1.96*SQRT(K18*(1-K18)/J18+1.96^2/(4*J18^2)))/(1+1.96^2/J18) -> 0.25822976 | M18: =(K18+1.96^2/(2*J18)+1.96*SQRT(K18*(1-K18)/J18+1.96^2/(4*J18^2)))/(1+1.96^2/J18) -> 0.43100105
A19: Fasta | B19: P3 | C19: Normal | D19: Claude | E19: Python | F19: It worked.
A20: Fasta | B20: P3 | C20: Normal | D20: DeepSeek | E20: Python | F20: Compiled ok. Wrong output. | H20: Gemini
A21: Fasta | B21: P3 | C21: Normal | D21: DeepSeek | E21: C | F21: Compiled ok. Wrong output. | H21: Stage | I21: Success | J21: Total | K21: % | L21: ic95_lo | M21: ic95_hi
A22: Fasta | B22: P3 | C22: Normal | D22: Gemini | E22: Python | F22: It did not compile. | H22: P(G=1) | I22: =COUNTIFS($D$2:$D$410,"Gemini",$F$2:$F$410,"<>No Code") -> 82 | J22: =COUNTIF($D$2:$D$410,"Gemini") -> 82 | K22: =I22/J22 -> 1 | L22: =(K22+1.96^2/(2*J22)-1.96*SQRT(K22*(1-K22)/J22+1.96^2/(4*J22^2)))/(1+1.96^2/J22) -> 0.95524781 | M22: =(K22+1.96^2/(2*J22)+1.96*SQRT(K22*(1-K22)/J22+1.96^2/(4*J22^2)))/(1+1.96^2/J22) -> 1
A23: Fasta | B23: P3 | C23: TBR | D23: ChatGPT | E23: Rust | F23: Compiled ok. Wrong output. | H23: P(R=1|G=1) | I23: =COUNTIFS($D$2:$D$410,"Gemini",$F$2:$F$410,"<>No Code",$F$2:$F$410,"<>It did not compile.") -> 79 | J23: =I22 -> 82 | K23: =I23/J23 -> 0.96341463 | L23: =(K23+1.96^2/(2*J23)-1.96*SQRT(K23*(1-K23)/J23+1.96^2/(4*J23^2)))/(1+1.96^2/J23) -> 0.89787097 | M23: =(K23+1.96^2/(2*J23)+1.96*SQRT(K23*(1-K23)/J23+1.96^2/(4*J23^2)))/(1+1.96^2/J23) -> 0.98748065
A24: Fasta | B24: P3 | C24: TBR | D24: Claude | E24: Python | F24: It worked. | H24: P(C=1|R=1) | I24: =COUNTIFS($D$2:$D$410,"Gemini",$F$2:$F$410,"It worked.") -> 73 | J24: =I23 -> 79 | K24: =I24/J24 -> 0.92405063 | L24: =(K24+1.96^2/(2*J24)-1.96*SQRT(K24*(1-K24)/J24+1.96^2/(4*J24^2)))/(1+1.96^2/J24) -> 0.84404397 | M24: =(K24+1.96^2/(2*J24)+1.96*SQRT(K24*(1-K24)/J24+1.96^2/(4*J24^2)))/(1+1.96^2/J24) -> 0.96472843
A25: Fasta | B25: P3 | C25: TBR | D25: DeepSeek | E25: Python | F25: It worked.
A26: Fasta | B26: P3 | C26: TBR | D26: Gemini | E26: Python | F26: It worked. | H26: Total
A27: Fasta | B27: P4 | C27: Normal | D27: ChatGPT | E27: Go | F27: It worked. | H27: Stage | I27: Success | J27: Total | K27: % | L27: ic95_lo | M27: ic95_hi
A28: Fasta | B28: P4 | C28: Normal | D28: Claude | E28: Python | F28: It worked. | H28: P(G=1) | I28: =COUNTIF($F$2:$F$410,"<>No Code") -> 394 | J28: =COUNTA($D$2:$D$410) -> 409 | K28: =I28/J28 -> 0.96332518 | L28: =(K28+1.96^2/(2*J28)-1.96*SQRT(K28*(1-K28)/J28+1.96^2/(4*J28^2)))/(1+1.96^2/J28) -> 0.94037674 | M28: =(K28+1.96^2/(2*J28)+1.96*SQRT(K28*(1-K28)/J28+1.96^2/(4*J28^2)))/(1+1.96^2/J28) -> 0.9776509
A29: Fasta | B29: P4 | C29: Normal | D29: DeepSeek | E29: Python | F29: It worked. | H29: P(R=1|G=1) | I29: =COUNTIFS($F$2:$F$410,"<>No Code",$F$2:$F$410,"<>It did not compile.") -> 364 | J29: =I28 -> 394 | K29: =I29/J29 -> 0.92385787 | L29: =(K29+1.96^2/(2*J29)-1.96*SQRT(K29*(1-K29)/J29+1.96^2/(4*J29^2)))/(1+1.96^2/J29) -> 0.89338314 | M29: =(K29+1.96^2/(2*J29)+1.96*SQRT(K29*(1-K29)/J29+1.96^2/(4*J29^2)))/(1+1.96^2/J29) -> 0.94614696
A30: Fasta | B30: P4 | C30: Normal | D30: Gemini | E30: Go | F30: It worked. | H30: P(C=1|R=1) | I30: =COUNTIFS($F$2:$F$410,"It worked.") -> 230 | J30: =I29 -> 364 | K30: =I30/J30 -> 0.63186813 | L30: =(K30+1.96^2/(2*J30)-1.96*SQRT(K30*(1-K30)/J30+1.96^2/(4*J30^2)))/(1+1.96^2/J30) -> 0.58118378 | M30: =(K30+1.96^2/(2*J30)+1.96*SQRT(K30*(1-K30)/J30+1.96^2/(4*J30^2)))/(1+1.96^2/J30) -> 0.67979812
A31: Fasta | B31: P4 | C31: TBR | D31: ChatGPT | E31: Go | F31: It worked.
A32: Fasta | B32: P4 | C32: TBR | D32: Claude | E32: C | F32: It worked.
A33: Fasta | B33: P4 | C33: TBR | D33: DeepSeek | E33: Python | F33: Compiled ok. Wrong output.
A34: Fasta | B34: P4 | C34: TBR | D34: Gemini | E34: C++ | F34: It worked.
A35: Binary-trees | B35: P1 | C35: Normal | D35: ChatGPT | E35: C | F35: It worked.
A36: Binary-trees | B36: P1 | C36: Normal | D36: Claude | E36: C++ | F36: It worked.
A37: Binary-trees | B37: P1 | C37: Normal | D37: Claude | E37: Java | F37: It worked.
A38: Binary-trees | B38: P1 | C38: Normal | D38: Claude | E38: Python | F38: It worked.
A39: Binary-trees | B39: P1 | C39: Normal | D39: Claude | E39: C# | F39: It worked.
A40: Binary-trees | B40: P1 | C40: Normal | D40: DeepSeek | E40: Java | F40: It did not compile.
...

Sheet all-data_no-duplicate 
A1: BENCHMARK | B1: PROMPT | C1: SEARCH TYPE | D1: AI TOOL | E1: P. L. | F1: OUTPUT COMMENT | G1: PAIRED OUTCOME
A2: Binary-trees | B2: P1 | C2: Normal | D2: ChatGPT | E2: C | F2: It worked. | G2: =IF(C2<>"Normal","",IF(COUNTIFS($A$2:$A$321,A2,$B$2:$B$321,B2,$D$2:$D$321,D2,$C$2:$C$321,"TBR")=0,"Pair not found",IF(AND(F2="It worked.",COUNTIFS($A$2:$A$321,A2,$B$2:$B$321,B2,$D$2:$D$321,D2,$C$2:$C$321,"TBR",$F$2:$F$321,"It worked.")>0),"Both success",IF(F2="It worked.","Normal success",IF(COUNTIFS($A$2:$A$321,A2,$B$2:$B$321,B2,$D$2:$D$321,D2,$C$2:$C$321,"TBR",$F$2:$F$321,"It worked.")>0,"TBR success","Both failed"))))) -> Both success | I2: ChatGPT | K2: TBR | O2: Claude | Q2: TBR | V2: Password: samepassword
A3: Binary-trees | B3: P1 | C3: TBR | D3: ChatGPT | E3: C | F3: It worked. | G3: =IF(C3<>"Normal","",IF(COUNTIFS($A$2:$A$321,A3,$B$2:$B$321,B3,$D$2:$D$321,D3,$C$2:$C$321,"TBR")=0,"Pair not found",IF(AND(F3="It worked.",COUNTIFS($A$2:$A$321,A3,$B$2:$B$321,B3,$D$2:$D$321,D3,$C$2:$C$321,"TBR",$F$2:$F$321,"It worked.")>0),"Both success",IF(F3="It worked.","Normal success",IF(COUNTIFS($A$2:$A$321,A3,$B$2:$B$321,B3,$D$2:$D$321,D3,$C$2:$C$321,"TBR",$F$2:$F$321,"It worked.")>0,"TBR success","Both failed"))))) | K3: Success | L3: Failed | M3: Total | Q3: Success | R3: Failed | S3: Total
A4: Binary-trees | B4: P2 | C4: Normal | D4: ChatGPT | E4: C | F4: Compiled ok. Wrong output. | G4: =IF(C4<>"Normal","",IF(COUNTIFS($A$2:$A$321,A4,$B$2:$B$321,B4,$D$2:$D$321,D4,$C$2:$C$321,"TBR")=0,"Pair not found",IF(AND(F4="It worked.",COUNTIFS($A$2:$A$321,A4,$B$2:$B$321,B4,$D$2:$D$321,D4,$C$2:$C$321,"TBR",$F$2:$F$321,"It worked.")>0),"Both success",IF(F4="It worked.","Normal success",IF(COUNTIFS($A$2:$A$321,A4,$B$2:$B$321,B4,$D$2:$D$321,D4,$C$2:$C$321,"TBR",$F$2:$F$321,"It worked.")>0,"TBR success","Both failed"))))) -> TBR success | I4: Normal | J4: Success | K4: =COUNTIFS($G$2:$G$321,"Both success",$D$2:$D$321,"ChatGPT") -> 18 | L4: =COUNTIFS($G$2:$G$321,"Normal success",$D$2:$D$321,"ChatGPT") -> 3 | M4: =SUM(K4:L4) -> 21 | O4: Normal | P4: Success | Q4: =COUNTIFS($G$2:$G$321,"Both success",$D$2:$D$321,"Claude") -> 18 | R4: =COUNTIFS($G$2:$G$321,"Normal success",$D$2:$D$321,"Claude") -> 4 | S4: =SUM(Q4:R4) -> 22
A5: Binary-trees | B5: P2 | C5: TBR | D5: ChatGPT | E5: Go | F5: It worked. | G5: =IF(C5<>"Normal","",IF(COUNTIFS($A$2:$A$321,A5,$B$2:$B$321,B5,$D$2:$D$321,D5,$C$2:$C$321,"TBR")=0,"Pair not found",IF(AND(F5="It worked.",COUNTIFS($A$2:$A$321,A5,$B$2:$B$321,B5,$D$2:$D$321,D5,$C$2:$C$321,"TBR",$F$2:$F$321,"It worked.")>0),"Both success",IF(F5="It worked.","Normal success",IF(COUNTIFS($A$2:$A$321,A5,$B$2:$B$321,B5,$D$2:$D$321,D5,$C$2:$C$321,"TBR",$F$2:$F$321,"It worked.")>0,"TBR success","Both failed"))))) | J5: Failed | K5: =COUNTIFS($G$2:$G$321,"TBR success",$D$2:$D$321,"ChatGPT") -> 6 | L5: =COUNTIFS($G$2:$G$321,"Both failed",$D$2:$D$321,"ChatGPT") -> 13 | M5: =SUM(K5:L5) -> 19 | P5: Failed | Q5: =COUNTIFS($G$2:$G$321,"TBR success",$D$2:$D$321,"Claude") -> 7 | R5: =COUNTIFS($G$2:$G$321,"Both failed",$D$2:$D$321,"Claude") -> 11 | S5: =SUM(Q5:R5) -> 18
A6: Binary-trees | B6: P3 | C6: Normal | D6: ChatGPT | E6: Go | F6: It worked. | G6: =IF(C6<>"Normal","",IF(COUNTIFS($A$2:$A$321,A6,$B$2:$B$321,B6,$D$2:$D$321,D6,$C$2:$C$321,"TBR")=0,"Pair not found",IF(AND(F6="It worked.",COUNTIFS($A$2:$A$321,A6,$B$2:$B$321,B6,$D$2:$D$321,D6,$C$2:$C$321,"TBR",$F$2:$F$321,"It worked.")>0),"Both success",IF(F6="It worked.","Normal success",IF(COUNTIFS($A$2:$A$321,A6,$B$2:$B$321,B6,$D$2:$D$321,D6,$C$2:$C$321,"TBR",$F$2:$F$321,"It worked.")>0,"TBR success","Both failed"))))) -> Both success | J6: Total | K6: =SUM(K4:K5) -> 24 | L6: =SUM(L4:L5) -> 16 | M6: =SUM(M4:M5) -> 40 | P6: Total | Q6: =SUM(Q4:Q5) -> 25 | R6: =SUM(R4:R5) -> 15 | S6: =SUM(S4:S5) -> 40
A7: Binary-trees | B7: P3 | C7: TBR | D7: ChatGPT | E7: Go | F7: It worked. | G7: =IF(C7<>"Normal","",IF(COUNTIFS($A$2:$A$321,A7,$B$2:$B$321,B7,$D$2:$D$321,D7,$C$2:$C$321,"TBR")=0,"Pair not found",IF(AND(F7="It worked.",COUNTIFS($A$2:$A$321,A7,$B$2:$B$321,B7,$D$2:$D$321,D7,$C$2:$C$321,"TBR",$F$2:$F$321,"It worked.")>0),"Both success",IF(F7="It worked.","Normal success",IF(COUNTIFS($A$2:$A$321,A7,$B$2:$B$321,B7,$D$2:$D$321,D7,$C$2:$C$321,"TBR",$F$2:$F$321,"It worked.")>0,"TBR success","Both failed")))))
A8: Binary-trees | B8: P4 | C8: Normal | D8: ChatGPT | E8: Go | F8: It worked. | G8: =IF(C8<>"Normal","",IF(COUNTIFS($A$2:$A$321,A8,$B$2:$B$321,B8,$D$2:$D$321,D8,$C$2:$C$321,"TBR")=0,"Pair not found",IF(AND(F8="It worked.",COUNTIFS($A$2:$A$321,A8,$B$2:$B$321,B8,$D$2:$D$321,D8,$C$2:$C$321,"TBR",$F$2:$F$321,"It worked.")>0),"Both success",IF(F8="It worked.","Normal success",IF(COUNTIFS($A$2:$A$321,A8,$B$2:$B$321,B8,$D$2:$D$321,D8,$C$2:$C$321,"TBR",$F$2:$F$321,"It worked.")>0,"TBR success","Both failed"))))) -> Both success | I8: DeepSeek | K8: TBR | O8: Gemini | Q8: TBR | U8: AI-ASSISTANT | V8: EXACT MCNEMAR TEST (p-value) | X8: ChatGPT
A9: Binary-trees | B9: P4 | C9: TBR | D9: ChatGPT | E9: Go | F9: It worked. | G9: =IF(C9<>"Normal","",IF(COUNTIFS($A$2:$A$321,A9,$B$2:$B$321,B9,$D$2:$D$321,D9,$C$2:$C$321,"TBR")=0,"Pair not found",IF(AND(F9="It worked.",COUNTIFS($A$2:$A$321,A9,$B$2:$B$321,B9,$D$2:$D$321,D9,$C$2:$C$321,"TBR",$F$2:$F$321,"It worked.")>0),"Both success",IF(F9="It worked.","Normal success",IF(COUNTIFS($A$2:$A$321,A9,$B$2:$B$321,B9,$D$2:$D$321,D9,$C$2:$C$321,"TBR",$F$2:$F$321,"It worked.")>0,"TBR success","Both failed"))))) | K9: Success | L9: Failed | M9: Total | Q9: Success | R9: Failed | S9: Total | U9: ChatGPT | V9: =2*BINOMDIST(MIN(L4,K5),L4+K5, 0.5, TRUE) -> 0.5078125 | X9: Stage | Y9: Success | Z9: Total | AA9: % | AB9: ic95_lo | AC9: ic95_hi | AE9: REFERENCE: | AF9: McNemar's Test: Comparing Paired Proportions — Formula, Examples & Calculator
A10: Fannkuch-redux | B10: P1 | C10: Normal | D10: ChatGPT | E10: C | F10: Compiled ok. Wrong output. | G10: =IF(C10<>"Normal","",IF(COUNTIFS($A$2:$A$321,A10,$B$2:$B$321,B10,$D$2:$D$321,D10,$C$2:$C$321,"TBR")=0,"Pair not found",IF(AND(F10="It worked.",COUNTIFS($A$2:$A$321,A10,$B$2:$B$321,B10,$D$2:$D$321,D10,$C$2:$C$321,"TBR",$F$2:$F$321,"It worked.")>0),"Both success",IF(F10="It worked.","Normal success",IF(COUNTIFS($A$2:$A$321,A10,$B$2:$B$321,B10,$D$2:$D$321,D10,$C$2:$C$321,"TBR",$F$2:$F$321,"It worked.")>0,"TBR success","Both failed"))))) -> TBR success | I10: Normal | J10: Success | K10: =COUNTIFS($G$2:$G$321,"Both success",$D$2:$D$321,"DeepSeek") -> 6 | L10: =COUNTIFS($G$2:$G$321,"Normal success",$D$2:$D$321,"DeepSeek") -> 5 | M10: =SUM(K10:L10) -> 11 | O10: Normal | P10: Success | Q10: =COUNTIFS($G$2:$G$321,"Both success",$D$2:$D$321,"Gemini") -> 34 | R10: =COUNTIFS($G$2:$G$321,"Normal success",$D$2:$D$321,"Gemini") -> 1 | S10: =SUM(Q10:R10) -> 35 | U10: Claude | V10: =2*BINOMDIST(MIN(R4,Q5),R4+Q5, 0.5, TRUE) -> 0.54882813 | X10: P(G=1) | Y10: =COUNTIFS($D$2:$D$321,"ChatGPT",$F$2:$F$321,"<>No Code") -> 65 | Z10: =COUNTIF($D$2:$D$321,"ChatGPT") -> 80 | AA10: =Y10/Z10 -> 0.8125 | AB10: =(AA10+1.96^2/(2*Z10)-1.96*SQRT(AA10*(1-AA10)/Z10+1.96^2/(4*Z10^2)))/(1+1.96^2/Z10) -> 0.71341474 | AC10: =(AA10+1.96^2/(2*Z10)+1.96*SQRT(AA10*(1-AA10)/Z10+1.96^2/(4*Z10^2)))/(1+1.96^2/Z10) -> 0.88294792 | AF10: Note on the sampling error of the difference between correlated proportions or percentages | Psychometrika | Springer Nature Link
A11: Fannkuch-redux | B11: P1 | C11: TBR | D11: ChatGPT | E11: C | F11: It worked. | G11: =IF(C11<>"Normal","",IF(COUNTIFS($A$2:$A$321,A11,$B$2:$B$321,B11,$D$2:$D$321,D11,$C$2:$C$321,"TBR")=0,"Pair not found",IF(AND(F11="It worked.",COUNTIFS($A$2:$A$321,A11,$B$2:$B$321,B11,$D$2:$D$321,D11,$C$2:$C$321,"TBR",$F$2:$F$321,"It worked.")>0),"Both success",IF(F11="It worked.","Normal success",IF(COUNTIFS($A$2:$A$321,A11,$B$2:$B$321,B11,$D$2:$D$321,D11,$C$2:$C$321,"TBR",$F$2:$F$321,"It worked.")>0,"TBR success","Both failed"))))) | J11: Failed | K11: =COUNTIFS($G$2:$G$321,"TBR success",$D$2:$D$321,"DeepSeek") -> 5 | L11: =COUNTIFS($G$2:$G$321,"Both failed",$D$2:$D$321,"DeepSeek") -> 24 | M11: =SUM(K11:L11) -> 29 | P11: Failed | Q11: =COUNTIFS($G$2:$G$321,"TBR success",$D$2:$D$321,"Gemini") -> 3 | R11: =COUNTIFS($G$2:$G$321,"Both failed",$D$2:$D$321,"Gemini") -> 2 | S11: =SUM(Q11:R11) -> 5 | U11: DeepSeek | V11: =2*BINOMDIST(MIN(L10,K11),L10+K11, 0.5, TRUE) -> 1.2460938 | X11: P(R=1|G=1) | Y11: =COUNTIFS($D$2:$D$321,"ChatGPT",$F$2:$F$321,"<>No Code",$F$2:$F$321,"<>It did not compile.") -> 62 | Z11: =Y10 -> 65 | AA11: =Y11/Z11 -> 0.95384615 | AB11: =(AA11+1.96^2/(2*Z11)-1.96*SQRT(AA11*(1-AA11)/Z11+1.96^2/(4*Z11^2)))/(1+1.96^2/Z11) -> 0.87285948 | AC11: =(AA11+1.96^2/(2*Z11)+1.96*SQRT(AA11*(1-AA11)/Z11+1.96^2/(4*Z11^2)))/(1+1.96^2/Z11) -> 0.98418045
A12: Fannkuch-redux | B12: P2 | C12: Normal | D12: ChatGPT | E12: No Code | F12: No Code | G12: =IF(C12<>"Normal","",IF(COUNTIFS($A$2:$A$321,A12,$B$2:$B$321,B12,$D$2:$D$321,D12,$C$2:$C$321,"TBR")=0,"Pair not found",IF(AND(F12="It worked.",COUNTIFS($A$2:$A$321,A12,$B$2:$B$321,B12,$D$2:$D$321,D12,$C$2:$C$321,"TBR",$F$2:$F$321,"It worked.")>0),"Both success",IF(F12="It worked.","Normal success",IF(COUNTIFS($A$2:$A$321,A12,$B$2:$B$321,B12,$D$2:$D$321,D12,$C$2:$C$321,"TBR",$F$2:$F$321,"It worked.")>0,"TBR success","Both failed"))))) -> Both failed | J12: Total | K12: =SUM(K10:K11) -> 11 | L12: =SUM(L10:L11) -> 29 | M12: =SUM(M10:M11) -> 40 | P12: Total | Q12: =SUM(Q10:Q11) -> 37 | R12: =SUM(R10:R11) -> 3 | S12: =SUM(S10:S11) -> 40 | U12: Gemini | V12: =2*BINOMDIST(MIN(R10,Q11),R10+Q11, 0.5, TRUE) -> 0.625 | X12: P(C=1|R=1) | Y12: =COUNTIFS($D$2:$D$321,"ChatGPT",$F$2:$F$321,"It worked.") -> 45 | Z12: =Y11 -> 62 | AA12: =Y12/Z12 -> 0.72580645 | AB12: =(AA12+1.96^2/(2*Z12)-1.96*SQRT(AA12*(1-AA12)/Z12+1.96^2/(4*Z12^2)))/(1+1.96^2/Z12) -> 0.60407224 | AC12: =(AA12+1.96^2/(2*Z12)+1.96*SQRT(AA12*(1-AA12)/Z12+1.96^2/(4*Z12^2)))/(1+1.96^2/Z12) -> 0.82119081
A13: Fannkuch-redux | B13: P2 | C13: TBR | D13: ChatGPT | E13: C | F13: It did not compile. | G13: =IF(C13<>"Normal","",IF(COUNTIFS($A$2:$A$321,A13,$B$2:$B$321,B13,$D$2:$D$321,D13,$C$2:$C$321,"TBR")=0,"Pair not found",IF(AND(F13="It worked.",COUNTIFS($A$2:$A$321,A13,$B$2:$B$321,B13,$D$2:$D$321,D13,$C$2:$C$321,"TBR",$F$2:$F$321,"It worked.")>0),"Both success",IF(F13="It worked.","Normal success",IF(COUNTIFS($A$2:$A$321,A13,$B$2:$B$321,B13,$D$2:$D$321,D13,$C$2:$C$321,"TBR",$F$2:$F$321,"It worked.")>0,"TBR success","Both failed")))))
A14: Fannkuch-redux | B14: P3 | C14: Normal | D14: ChatGPT | E14: C | F14: Compiled ok. Wrong output. | G14: =IF(C14<>"Normal","",IF(COUNTIFS($A$2:$A$321,A14,$B$2:$B$321,B14,$D$2:$D$321,D14,$C$2:$C$321,"TBR")=0,"Pair not found",IF(AND(F14="It worked.",COUNTIFS($A$2:$A$321,A14,$B$2:$B$321,B14,$D$2:$D$321,D14,$C$2:$C$321,"TBR",$F$2:$F$321,"It worked.")>0),"Both success",IF(F14="It worked.","Normal success",IF(COUNTIFS($A$2:$A$321,A14,$B$2:$B$321,B14,$D$2:$D$321,D14,$C$2:$C$321,"TBR",$F$2:$F$321,"It worked.")>0,"TBR success","Both failed"))))) -> Both failed | X14: Claude
A15: Fannkuch-redux | B15: P3 | C15: TBR | D15: ChatGPT | E15: C | F15: Compiled ok. Wrong output. | G15: =IF(C15<>"Normal","",IF(COUNTIFS($A$2:$A$321,A15,$B$2:$B$321,B15,$D$2:$D$321,D15,$C$2:$C$321,"TBR")=0,"Pair not found",IF(AND(F15="It worked.",COUNTIFS($A$2:$A$321,A15,$B$2:$B$321,B15,$D$2:$D$321,D15,$C$2:$C$321,"TBR",$F$2:$F$321,"It worked.")>0),"Both success",IF(F15="It worked.","Normal success",IF(COUNTIFS($A$2:$A$321,A15,$B$2:$B$321,B15,$D$2:$D$321,D15,$C$2:$C$321,"TBR",$F$2:$F$321,"It worked.")>0,"TBR success","Both failed"))))) | X15: Stage | Y15: Success | Z15: Total | AA15: % | AB15: ic95_lo | AC15: ic95_hi
A16: Fannkuch-redux | B16: P4 | C16: Normal | D16: ChatGPT | E16: C | F16: Compiled ok. Wrong output. | G16: =IF(C16<>"Normal","",IF(COUNTIFS($A$2:$A$321,A16,$B$2:$B$321,B16,$D$2:$D$321,D16,$C$2:$C$321,"TBR")=0,"Pair not found",IF(AND(F16="It worked.",COUNTIFS($A$2:$A$321,A16,$B$2:$B$321,B16,$D$2:$D$321,D16,$C$2:$C$321,"TBR",$F$2:$F$321,"It worked.")>0),"Both success",IF(F16="It worked.","Normal success",IF(COUNTIFS($A$2:$A$321,A16,$B$2:$B$321,B16,$D$2:$D$321,D16,$C$2:$C$321,"TBR",$F$2:$F$321,"It worked.")>0,"TBR success","Both failed"))))) -> Both failed | X16: P(G=1) | Y16: =COUNTIFS($D$2:$D$499,"Claude",$F$2:$F$499,"<>No Code") -> 80 | Z16: =COUNTIF($D$2:$D$321,"Claude") -> 80 | AA16: =Y16/Z16 -> 1 | AB16: =(AA16+1.96^2/(2*Z16)-1.96*SQRT(AA16*(1-AA16)/Z16+1.96^2/(4*Z16^2)))/(1+1.96^2/Z16) -> 0.95418026 | AC16: =(AA16+1.96^2/(2*Z16)+1.96*SQRT(AA16*(1-AA16)/Z16+1.96^2/(4*Z16^2)))/(1+1.96^2/Z16) -> 1
A17: Fannkuch-redux | B17: P4 | C17: TBR | D17: ChatGPT | E17: C | F17: Compiled ok. Wrong output. | G17: =IF(C17<>"Normal","",IF(COUNTIFS($A$2:$A$321,A17,$B$2:$B$321,B17,$D$2:$D$321,D17,$C$2:$C$321,"TBR")=0,"Pair not found",IF(AND(F17="It worked.",COUNTIFS($A$2:$A$321,A17,$B$2:$B$321,B17,$D$2:$D$321,D17,$C$2:$C$321,"TBR",$F$2:$F$321,"It worked.")>0),"Both success",IF(F17="It worked.","Normal success",IF(COUNTIFS($A$2:$A$321,A17,$B$2:$B$321,B17,$D$2:$D$321,D17,$C$2:$C$321,"TBR",$F$2:$F$321,"It worked.")>0,"TBR success","Both failed"))))) | X17: P(R=1|G=1) | Y17: =COUNTIFS($D$2:$D$499,"Claude",$F$2:$F$499,"<>No Code",$F$2:$F$499,"<>It did not compile.") -> 78 | Z17: =Y16 -> 80 | AA17: =Y17/Z17 -> 0.975 | AB17: =(AA17+1.96^2/(2*Z17)-1.96*SQRT(AA17*(1-AA17)/Z17+1.96^2/(4*Z17^2)))/(1+1.96^2/Z17) -> 0.913354 | AC17: =(AA17+1.96^2/(2*Z17)+1.96*SQRT(AA17*(1-AA17)/Z17+1.96^2/(4*Z17^2)))/(1+1.96^2/Z17) -> 0.99311725
A18: Fasta | B18: P1 | C18: Normal | D18: ChatGPT | E18: Python | F18: It worked. | G18: =IF(C18<>"Normal","",IF(COUNTIFS($A$2:$A$321,A18,$B$2:$B$321,B18,$D$2:$D$321,D18,$C$2:$C$321,"TBR")=0,"Pair not found",IF(AND(F18="It worked.",COUNTIFS($A$2:$A$321,A18,$B$2:$B$321,B18,$D$2:$D$321,D18,$C$2:$C$321,"TBR",$F$2:$F$321,"It worked.")>0),"Both success",IF(F18="It worked.","Normal success",IF(COUNTIFS($A$2:$A$321,A18,$B$2:$B$321,B18,$D$2:$D$321,D18,$C$2:$C$321,"TBR",$F$2:$F$321,"It worked.")>0,"TBR success","Both failed"))))) -> Both success | X18: P(C=1|R=1) | Y18: =COUNTIFS($D$2:$D$499,"Claude",$F$2:$F$499,"It worked.") -> 47 | Z18: =Y17 -> 78 | AA18: =Y18/Z18 -> 0.6025641 | AB18: =(AA18+1.96^2/(2*Z18)-1.96*SQRT(AA18*(1-AA18)/Z18+1.96^2/(4*Z18^2)))/(1+1.96^2/Z18) -> 0.49161655 | AC18: =(AA18+1.96^2/(2*Z18)+1.96*SQRT(AA18*(1-AA18)/Z18+1.96^2/(4*Z18^2)))/(1+1.96^2/Z18) -> 0.70388305
A19: Fasta | B19: P1 | C19: TBR | D19: ChatGPT | E19: Python | F19: It worked. | G19: =IF(C19<>"Normal","",IF(COUNTIFS($A$2:$A$321,A19,$B$2:$B$321,B19,$D$2:$D$321,D19,$C$2:$C$321,"TBR")=0,"Pair not found",IF(AND(F19="It worked.",COUNTIFS($A$2:$A$321,A19,$B$2:$B$321,B19,$D$2:$D$321,D19,$C$2:$C$321,"TBR",$F$2:$F$321,"It worked.")>0),"Both success",IF(F19="It worked.","Normal success",IF(COUNTIFS($A$2:$A$321,A19,$B$2:$B$321,B19,$D$2:$D$321,D19,$C$2:$C$321,"TBR",$F$2:$F$321,"It worked.")>0,"TBR success","Both failed")))))
A20: Fasta | B20: P2 | C20: Normal | D20: ChatGPT | E20: Go | F20: It worked. | G20: =IF(C20<>"Normal","",IF(COUNTIFS($A$2:$A$321,A20,$B$2:$B$321,B20,$D$2:$D$321,D20,$C$2:$C$321,"TBR")=0,"Pair not found",IF(AND(F20="It worked.",COUNTIFS($A$2:$A$321,A20,$B$2:$B$321,B20,$D$2:$D$321,D20,$C$2:$C$321,"TBR",$F$2:$F$321,"It worked.")>0),"Both success",IF(F20="It worked.","Normal success",IF(COUNTIFS($A$2:$A$321,A20,$B$2:$B$321,B20,$D$2:$D$321,D20,$C$2:$C$321,"TBR",$F$2:$F$321,"It worked.")>0,"TBR success","Both failed"))))) -> Both success | X20: DeepSeek
A21: Fasta | B21: P2 | C21: TBR | D21: ChatGPT | E21: Rust | F21: It worked. | G21: =IF(C21<>"Normal","",IF(COUNTIFS($A$2:$A$321,A21,$B$2:$B$321,B21,$D$2:$D$321,D21,$C$2:$C$321,"TBR")=0,"Pair not found",IF(AND(F21="It worked.",COUNTIFS($A$2:$A$321,A21,$B$2:$B$321,B21,$D$2:$D$321,D21,$C$2:$C$321,"TBR",$F$2:$F$321,"It worked.")>0),"Both success",IF(F21="It worked.","Normal success",IF(COUNTIFS($A$2:$A$321,A21,$B$2:$B$321,B21,$D$2:$D$321,D21,$C$2:$C$321,"TBR",$F$2:$F$321,"It worked.")>0,"TBR success","Both failed"))))) | X21: Stage | Y21: Success | Z21: Total | AA21: % | AB21: ic95_lo | AC21: ic95_hi
A22: Fasta | B22: P3 | C22: Normal | D22: ChatGPT | E22: Go | F22: It worked. | G22: =IF(C22<>"Normal","",IF(COUNTIFS($A$2:$A$321,A22,$B$2:$B$321,B22,$D$2:$D$321,D22,$C$2:$C$321,"TBR")=0,"Pair not found",IF(AND(F22="It worked.",COUNTIFS($A$2:$A$321,A22,$B$2:$B$321,B22,$D$2:$D$321,D22,$C$2:$C$321,"TBR",$F$2:$F$321,"It worked.")>0),"Both success",IF(F22="It worked.","Normal success",IF(COUNTIFS($A$2:$A$321,A22,$B$2:$B$321,B22,$D$2:$D$321,D22,$C$2:$C$321,"TBR",$F$2:$F$321,"It worked.")>0,"TBR success","Both failed"))))) -> Normal success | X22: P(G=1) | Y22: =COUNTIFS($D$2:$D$321,"DeepSeek",$F$2:$F$321,"<>No Code") -> 80 | Z22: =COUNTIF($D$2:$D$321,"DeepSeek") -> 80 | AA22: =Y22/Z22 -> 1 | AB22: =(AA22+1.96^2/(2*Z22)-1.96*SQRT(AA22*(1-AA22)/Z22+1.96^2/(4*Z22^2)))/(1+1.96^2/Z22) -> 0.95418026 | AC22: =(AA22+1.96^2/(2*Z22)+1.96*SQRT(AA22*(1-AA22)/Z22+1.96^2/(4*Z22^2)))/(1+1.96^2/Z22) -> 1
A23: Fasta | B23: P3 | C23: TBR | D23: ChatGPT | E23: Rust | F23: Compiled ok. Wrong output. | G23: =IF(C23<>"Normal","",IF(COUNTIFS($A$2:$A$321,A23,$B$2:$B$321,B23,$D$2:$D$321,D23,$C$2:$C$321,"TBR")=0,"Pair not found",IF(AND(F23="It worked.",COUNTIFS($A$2:$A$321,A23,$B$2:$B$321,B23,$D$2:$D$321,D23,$C$2:$C$321,"TBR",$F$2:$F$321,"It worked.")>0),"Both success",IF(F23="It worked.","Normal success",IF(COUNTIFS($A$2:$A$321,A23,$B$2:$B$321,B23,$D$2:$D$321,D23,$C$2:$C$321,"TBR",$F$2:$F$321,"It worked.")>0,"TBR success","Both failed"))))) | X23: P(R=1|G=1) | Y23: =COUNTIFS($D$2:$D$321,"DeepSeek",$F$2:$F$321,"<>No Code",$F$2:$F$321,"<>It did not compile.") -> 68 | Z23: =Y22 -> 80 | AA23: =Y23/Z23 -> 0.85 | AB23: =(AA23+1.96^2/(2*Z23)-1.96*SQRT(AA23*(1-AA23)/Z23+1.96^2/(4*Z23^2)))/(1+1.96^2/Z23) -> 0.75586572 | AC23: =(AA23+1.96^2/(2*Z23)+1.96*SQRT(AA23*(1-AA23)/Z23+1.96^2/(4*Z23^2)))/(1+1.96^2/Z23) -> 0.91206046
A24: Fasta | B24: P4 | C24: Normal | D24: ChatGPT | E24: Go | F24: It worked. | G24: =IF(C24<>"Normal","",IF(COUNTIFS($A$2:$A$321,A24,$B$2:$B$321,B24,$D$2:$D$321,D24,$C$2:$C$321,"TBR")=0,"Pair not found",IF(AND(F24="It worked.",COUNTIFS($A$2:$A$321,A24,$B$2:$B$321,B24,$D$2:$D$321,D24,$C$2:$C$321,"TBR",$F$2:$F$321,"It worked.")>0),"Both success",IF(F24="It worked.","Normal success",IF(COUNTIFS($A$2:$A$321,A24,$B$2:$B$321,B24,$D$2:$D$321,D24,$C$2:$C$321,"TBR",$F$2:$F$321,"It worked.")>0,"TBR success","Both failed"))))) -> Both success | X24: P(C=1|R=1) | Y24: =COUNTIFS($D$2:$D$321,"DeepSeek",$F$2:$F$321,"It worked.") -> 22 | Z24: =Y23 -> 68 | AA24: =Y24/Z24 -> 0.32352941 | AB24: =(AA24+1.96^2/(2*Z24)-1.96*SQRT(AA24*(1-AA24)/Z24+1.96^2/(4*Z24^2)))/(1+1.96^2/Z24) -> 0.22437447 | AC24: =(AA24+1.96^2/(2*Z24)+1.96*SQRT(AA24*(1-AA24)/Z24+1.96^2/(4*Z24^2)))/(1+1.96^2/Z24) -> 0.44155725
A25: Fasta | B25: P4 | C25: TBR | D25: ChatGPT | E25: Go | F25: It worked. | G25: =IF(C25<>"Normal","",IF(COUNTIFS($A$2:$A$321,A25,$B$2:$B$321,B25,$D$2:$D$321,D25,$C$2:$C$321,"TBR")=0,"Pair not found",IF(AND(F25="It worked.",COUNTIFS($A$2:$A$321,A25,$B$2:$B$321,B25,$D$2:$D$321,D25,$C$2:$C$321,"TBR",$F$2:$F$321,"It worked.")>0),"Both success",IF(F25="It worked.","Normal success",IF(COUNTIFS($A$2:$A$321,A25,$B$2:$B$321,B25,$D$2:$D$321,D25,$C$2:$C$321,"TBR",$F$2:$F$321,"It worked.")>0,"TBR success","Both failed")))))
A26: K-nucleotide | B26: P1 | C26: Normal | D26: ChatGPT | E26: Rust | F26: It worked. | G26: =IF(C26<>"Normal","",IF(COUNTIFS($A$2:$A$321,A26,$B$2:$B$321,B26,$D$2:$D$321,D26,$C$2:$C$321,"TBR")=0,"Pair not found",IF(AND(F26="It worked.",COUNTIFS($A$2:$A$321,A26,$B$2:$B$321,B26,$D$2:$D$321,D26,$C$2:$C$321,"TBR",$F$2:$F$321,"It worked.")>0),"Both success",IF(F26="It worked.","Normal success",IF(COUNTIFS($A$2:$A$321,A26,$B$2:$B$321,B26,$D$2:$D$321,D26,$C$2:$C$321,"TBR",$F$2:$F$321,"It worked.")>0,"TBR success","Both failed"))))) -> Both success | X26: Gemini
A27: K-nucleotide | B27: P1 | C27: TBR | D27: ChatGPT | E27: Rust | F27: It worked. | G27: =IF(C27<>"Normal","",IF(COUNTIFS($A$2:$A$321,A27,$B$2:$B$321,B27,$D$2:$D$321,D27,$C$2:$C$321,"TBR")=0,"Pair not found",IF(AND(F27="It worked.",COUNTIFS($A$2:$A$321,A27,$B$2:$B$321,B27,$D$2:$D$321,D27,$C$2:$C$321,"TBR",$F$2:$F$321,"It worked.")>0),"Both success",IF(F27="It worked.","Normal success",IF(COUNTIFS($A$2:$A$321,A27,$B$2:$B$321,B27,$D$2:$D$321,D27,$C$2:$C$321,"TBR",$F$2:$F$321,"It worked.")>0,"TBR success","Both failed"))))) | X27: Stage | Y27: Success | Z27: Total | AA27: % | AB27: ic95_lo | AC27: ic95_hi
A28: K-nucleotide | B28: P2 | C28: Normal | D28: ChatGPT | E28: Go | F28: Compiled ok. Wrong output. | G28: =IF(C28<>"Normal","",IF(COUNTIFS($A$2:$A$321,A28,$B$2:$B$321,B28,$D$2:$D$321,D28,$C$2:$C$321,"TBR")=0,"Pair not found",IF(AND(F28="It worked.",COUNTIFS($A$2:$A$321,A28,$B$2:$B$321,B28,$D$2:$D$321,D28,$C$2:$C$321,"TBR",$F$2:$F$321,"It worked.")>0),"Both success",IF(F28="It worked.","Normal success",IF(COUNTIFS($A$2:$A$321,A28,$B$2:$B$321,B28,$D$2:$D$321,D28,$C$2:$C$321,"TBR",$F$2:$F$321,"It worked.")>0,"TBR success","Both failed"))))) -> Both failed | X28: P(G=1) | Y28: =COUNTIFS($D$2:$D$321,"Gemini",$F$2:$F$321,"<>No Code") -> 80 | Z28: =COUNTIF($D$2:$D$321,"Gemini") -> 80 | AA28: =Y28/Z28 -> 1 | AB28: =(AA28+1.96^2/(2*Z28)-1.96*SQRT(AA28*(1-AA28)/Z28+1.96^2/(4*Z28^2)))/(1+1.96^2/Z28) -> 0.95418026 | AC28: =(AA28+1.96^2/(2*Z28)+1.96*SQRT(AA28*(1-AA28)/Z28+1.96^2/(4*Z28^2)))/(1+1.96^2/Z28) -> 1
A29: K-nucleotide | B29: P2 | C29: TBR | D29: ChatGPT | E29: Go | F29: Compiled ok. Wrong output. | G29: =IF(C29<>"Normal","",IF(COUNTIFS($A$2:$A$321,A29,$B$2:$B$321,B29,$D$2:$D$321,D29,$C$2:$C$321,"TBR")=0,"Pair not found",IF(AND(F29="It worked.",COUNTIFS($A$2:$A$321,A29,$B$2:$B$321,B29,$D$2:$D$321,D29,$C$2:$C$321,"TBR",$F$2:$F$321,"It worked.")>0),"Both success",IF(F29="It worked.","Normal success",IF(COUNTIFS($A$2:$A$321,A29,$B$2:$B$321,B29,$D$2:$D$321,D29,$C$2:$C$321,"TBR",$F$2:$F$321,"It worked.")>0,"TBR success","Both failed"))))) | X29: P(R=1|G=1) | Y29: =COUNTIFS($D$2:$D$321,"Gemini",$F$2:$F$321,"<>No Code",$F$2:$F$321,"<>It did not compile.") -> 78 | Z29: =Y28 -> 80 | AA29: =Y29/Z29 -> 0.975 | AB29: =(AA29+1.96^2/(2*Z29)-1.96*SQRT(AA29*(1-AA29)/Z29+1.96^2/(4*Z29^2)))/(1+1.96^2/Z29) -> 0.913354 | AC29: =(AA29+1.96^2/(2*Z29)+1.96*SQRT(AA29*(1-AA29)/Z29+1.96^2/(4*Z29^2)))/(1+1.96^2/Z29) -> 0.99311725
A30: K-nucleotide | B30: P3 | C30: Normal | D30: ChatGPT | E30: Python | F30: It worked. | G30: =IF(C30<>"Normal","",IF(COUNTIFS($A$2:$A$321,A30,$B$2:$B$321,B30,$D$2:$D$321,D30,$C$2:$C$321,"TBR")=0,"Pair not found",IF(AND(F30="It worked.",COUNTIFS($A$2:$A$321,A30,$B$2:$B$321,B30,$D$2:$D$321,D30,$C$2:$C$321,"TBR",$F$2:$F$321,"It worked.")>0),"Both success",IF(F30="It worked.","Normal success",IF(COUNTIFS($A$2:$A$321,A30,$B$2:$B$321,B30,$D$2:$D$321,D30,$C$2:$C$321,"TBR",$F$2:$F$321,"It worked.")>0,"TBR success","Both failed"))))) -> Both success | X30: P(C=1|R=1) | Y30: =COUNTIFS($D$2:$D$321,"Gemini",$F$2:$F$321,"It worked.") -> 72 | Z30: =Y29 -> 78 | AA30: =Y30/Z30 -> 0.92307692 | AB30: =(AA30+1.96^2/(2*Z30)-1.96*SQRT(AA30*(1-AA30)/Z30+1.96^2/(4*Z30^2)))/(1+1.96^2/Z30) -> 0.84216582 | AC30: =(AA30+1.96^2/(2*Z30)+1.96*SQRT(AA30*(1-AA30)/Z30+1.96^2/(4*Z30^2)))/(1+1.96^2/Z30) -> 0.96427002
A31: K-nucleotide | B31: P3 | C31: TBR | D31: ChatGPT | E31: Rust | F31: It worked. | G31: =IF(C31<>"Normal","",IF(COUNTIFS($A$2:$A$321,A31,$B$2:$B$321,B31,$D$2:$D$321,D31,$C$2:$C$321,"TBR")=0,"Pair not found",IF(AND(F31="It worked.",COUNTIFS($A$2:$A$321,A31,$B$2:$B$321,B31,$D$2:$D$321,D31,$C$2:$C$321,"TBR",$F$2:$F$321,"It worked.")>0),"Both success",IF(F31="It worked.","Normal success",IF(COUNTIFS($A$2:$A$321,A31,$B$2:$B$321,B31,$D$2:$D$321,D31,$C$2:$C$321,"TBR",$F$2:$F$321,"It worked.")>0,"TBR success","Both failed")))))
A32: K-nucleotide | B32: P4 | C32: Normal | D32: ChatGPT | E32: Go | F32: It worked. | G32: =IF(C32<>"Normal","",IF(COUNTIFS($A$2:$A$321,A32,$B$2:$B$321,B32,$D$2:$D$321,D32,$C$2:$C$321,"TBR")=0,"Pair not found",IF(AND(F32="It worked.",COUNTIFS($A$2:$A$321,A32,$B$2:$B$321,B32,$D$2:$D$321,D32,$C$2:$C$321,"TBR",$F$2:$F$321,"It worked.")>0),"Both success",IF(F32="It worked.","Normal success",IF(COUNTIFS($A$2:$A$321,A32,$B$2:$B$321,B32,$D$2:$D$321,D32,$C$2:$C$321,"TBR",$F$2:$F$321,"It worked.")>0,"TBR success","Both failed"))))) -> Both success | X32: Total
A33: K-nucleotide | B33: P4 | C33: TBR | D33: ChatGPT | E33: Go | F33: It worked. | G33: =IF(C33<>"Normal","",IF(COUNTIFS($A$2:$A$321,A33,$B$2:$B$321,B33,$D$2:$D$321,D33,$C$2:$C$321,"TBR")=0,"Pair not found",IF(AND(F33="It worked.",COUNTIFS($A$2:$A$321,A33,$B$2:$B$321,B33,$D$2:$D$321,D33,$C$2:$C$321,"TBR",$F$2:$F$321,"It worked.")>0),"Both success",IF(F33="It worked.","Normal success",IF(COUNTIFS($A$2:$A$321,A33,$B$2:$B$321,B33,$D$2:$D$321,D33,$C$2:$C$321,"TBR",$F$2:$F$321,"It worked.")>0,"TBR success","Both failed"))))) | X33: Stage | Y33: Success | Z33: Total | AA33: % | AB33: ic95_lo | AC33: ic95_hi
A34: Mandelbrot | B34: P1 | C34: Normal | D34: ChatGPT | E34: C | F34: It worked. | G34: =IF(C34<>"Normal","",IF(COUNTIFS($A$2:$A$321,A34,$B$2:$B$321,B34,$D$2:$D$321,D34,$C$2:$C$321,"TBR")=0,"Pair not found",IF(AND(F34="It worked.",COUNTIFS($A$2:$A$321,A34,$B$2:$B$321,B34,$D$2:$D$321,D34,$C$2:$C$321,"TBR",$F$2:$F$321,"It worked.")>0),"Both success",IF(F34="It worked.","Normal success",IF(COUNTIFS($A$2:$A$321,A34,$B$2:$B$321,B34,$D$2:$D$321,D34,$C$2:$C$321,"TBR",$F$2:$F$321,"It worked.")>0,"TBR success","Both failed"))))) -> Both success | X34: P(G=1) | Y34: =COUNTIF($F$2:$F$321,"<>No Code") -> 305 | Z34: =COUNTA($D$2:$D$499) -> 320 | AA34: =Y34/Z34 -> 0.953125 | AB34: =(AA34+1.96^2/(2*Z34)-1.96*SQRT(AA34*(1-AA34)/Z34+1.96^2/(4*Z34^2)))/(1+1.96^2/Z34) -> 0.92410898 | AC34: =(AA34+1.96^2/(2*Z34)+1.96*SQRT(AA34*(1-AA34)/Z34+1.96^2/(4*Z34^2)))/(1+1.96^2/Z34) -> 0.97139055
A35: Mandelbrot | B35: P1 | C35: TBR | D35: ChatGPT | E35: C | F35: It worked. | G35: =IF(C35<>"Normal","",IF(COUNTIFS($A$2:$A$321,A35,$B$2:$B$321,B35,$D$2:$D$321,D35,$C$2:$C$321,"TBR")=0,"Pair not found",IF(AND(F35="It worked.",COUNTIFS($A$2:$A$321,A35,$B$2:$B$321,B35,$D$2:$D$321,D35,$C$2:$C$321,"TBR",$F$2:$F$321,"It worked.")>0),"Both success",IF(F35="It worked.","Normal success",IF(COUNTIFS($A$2:$A$321,A35,$B$2:$B$321,B35,$D$2:$D$321,D35,$C$2:$C$321,"TBR",$F$2:$F$321,"It worked.")>0,"TBR success","Both failed"))))) | X35: P(R=1|G=1) | Y35: =COUNTIFS($F$2:$F$321,"<>No Code",$F$2:$F$321,"<>It did not compile.") -> 286 | Z35: =Y34 -> 305 | AA35: =Y35/Z35 -> 0.93770492 | AB35: =(AA35+1.96^2/(2*Z35)-1.96*SQRT(AA35*(1-AA35)/Z35+1.96^2/(4*Z35^2)))/(1+1.96^2/Z35) -> 0.90476053 | AC35: =(AA35+1.96^2/(2*Z35)+1.96*SQRT(AA35*(1-AA35)/Z35+1.96^2/(4*Z35^2)))/(1+1.96^2/Z35) -> 0.95976031
A36: Mandelbrot | B36: P2 | C36: Normal | D36: ChatGPT | E36: C | F36: It worked. | G36: =IF(C36<>"Normal","",IF(COUNTIFS($A$2:$A$321,A36,$B$2:$B$321,B36,$D$2:$D$321,D36,$C$2:$C$321,"TBR")=0,"Pair not found",IF(AND(F36="It worked.",COUNTIFS($A$2:$A$321,A36,$B$2:$B$321,B36,$D$2:$D$321,D36,$C$2:$C$321,"TBR",$F$2:$F$321,"It worked.")>0),"Both success",IF(F36="It worked.","Normal success",IF(COUNTIFS($A$2:$A$321,A36,$B$2:$B$321,B36,$D$2:$D$321,D36,$C$2:$C$321,"TBR",$F$2:$F$321,"It worked.")>0,"TBR success","Both failed"))))) -> Both success | X36: P(C=1|R=1) | Y36: =COUNTIFS($F$2:$F$321,"It worked.") -> 186 | Z36: =Y35 -> 286 | AA36: =Y36/Z36 -> 0.65034965 | AB36: =(AA36+1.96^2/(2*Z36)-1.96*SQRT(AA36*(1-AA36)/Z36+1.96^2/(4*Z36^2)))/(1+1.96^2/Z36) -> 0.59342152 | AC36: =(AA36+1.96^2/(2*Z36)+1.96*SQRT(AA36*(1-AA36)/Z36+1.96^2/(4*Z36^2)))/(1+1.96^2/Z36) -> 0.70329227
A37: Mandelbrot | B37: P2 | C37: TBR | D37: ChatGPT | E37: C | F37: It worked. | G37: =IF(C37<>"Normal","",IF(COUNTIFS($A$2:$A$321,A37,$B$2:$B$321,B37,$D$2:$D$321,D37,$C$2:$C$321,"TBR")=0,"Pair not found",IF(AND(F37="It worked.",COUNTIFS($A$2:$A$321,A37,$B$2:$B$321,B37,$D$2:$D$321,D37,$C$2:$C$321,"TBR",$F$2:$F$321,"It worked.")>0),"Both success",IF(F37="It worked.","Normal success",IF(COUNTIFS($A$2:$A$321,A37,$B$2:$B$321,B37,$D$2:$D$321,D37,$C$2:$C$321,"TBR",$F$2:$F$321,"It worked.")>0,"TBR success","Both failed")))))
A38: Mandelbrot | B38: P3 | C38: Normal | D38: ChatGPT | E38: C | F38: It worked. | G38: =IF(C38<>"Normal","",IF(COUNTIFS($A$2:$A$321,A38,$B$2:$B$321,B38,$D$2:$D$321,D38,$C$2:$C$321,"TBR")=0,"Pair not found",IF(AND(F38="It worked.",COUNTIFS($A$2:$A$321,A38,$B$2:$B$321,B38,$D$2:$D$321,D38,$C$2:$C$321,"TBR",$F$2:$F$321,"It worked.")>0),"Both success",IF(F38="It worked.","Normal success",IF(COUNTIFS($A$2:$A$321,A38,$B$2:$B$321,B38,$D$2:$D$321,D38,$C$2:$C$321,"TBR",$F$2:$F$321,"It worked.")>0,"TBR success","Both failed"))))) -> Both success
A39: Mandelbrot | B39: P3 | C39: TBR | D39: ChatGPT | E39: C | F39: It worked. | G39: =IF(C39<>"Normal","",IF(COUNTIFS($A$2:$A$321,A39,$B$2:$B$321,B39,$D$2:$D$321,D39,$C$2:$C$321,"TBR")=0,"Pair not found",IF(AND(F39="It worked.",COUNTIFS($A$2:$A$321,A39,$B$2:$B$321,B39,$D$2:$D$321,D39,$C$2:$C$321,"TBR",$F$2:$F$321,"It worked.")>0),"Both success",IF(F39="It worked.","Normal success",IF(COUNTIFS($A$2:$A$321,A39,$B$2:$B$321,B39,$D$2:$D$321,D39,$C$2:$C$321,"TBR",$F$2:$F$321,"It worked.")>0,"TBR success","Both failed")))))
A40: Mandelbrot | B40: P4 | C40: Normal | D40: ChatGPT | E40: C | F40: Compiled ok. Wrong output. | G40: =IF(C40<>"Normal","",IF(COUNTIFS($A$2:$A$321,A40,$B$2:$B$321,B40,$D$2:$D$321,D40,$C$2:$C$321,"TBR")=0,"Pair not found",IF(AND(F40="It worked.",COUNTIFS($A$2:$A$321,A40,$B$2:$B$321,B40,$D$2:$D$321,D40,$C$2:$C$321,"TBR",$F$2:$F$321,"It worked.")>0),"Both success",IF(F40="It worked.","Normal success",IF(COUNTIFS($A$2:$A$321,A40,$B$2:$B$321,B40,$D$2:$D$321,D40,$C$2:$C$321,"TBR",$F$2:$F$321,"It worked.")>0,"TBR success","Both failed"))))) -> TBR success
...

Sheet Recurrence
A2: P. L. | B2: Count of P. L. | D2: Count of OUTPUT COMMENT | E2: OUTPUT COMMENT | M2: Count of P. L. | N2: P. L.
A3: Bash (.sh) | B3: 2 | D3: BENCHMARK | E3: Compiled ok. Wrong output. | F3: It did not compile. | G3: It worked. | H3: No Code | I3: Compile ok. Wrong output. | J3: Grand Total | M3: PROMPT | N3: Bash (.sh) | O3: C | P3: C# | Q3: C++ | R3: Go | S3: Java | T3: JavaScript | U3: Julia | V3: No Code | W3: Python | X3: Ruby | Y3: Rust | Z3: Grand Total
A4: C | B4: 46 | D4: Binary-trees | E4: 8 | F4: 6 | G4: 47 | J4: 61 | M4: P1 | N4: 1 | O4: 12 | P4: 1 | Q4: 4 | R4: 2 | S4: 10 | T4: 2 | V4: 5 | W4: 67 | Y4: 5 | Z4: 109
A5: C# | B5: 3 | D5: Fannkuch-redux | E5: 27 | F5: 6 | G5: 10 | H5: 1 | J5: 44 | M5: P2 | N5: 1 | O5: 11 | Q5: 11 | R5: 14 | V5: 5 | W5: 42 | Y5: 7 | Z5: 91
A6: C++ | B6: 30 | D6: Fasta | E6: 5 | F6: 2 | G6: 26 | J6: 33 | M6: P3 | O6: 12 | Q6: 8 | R6: 5 | S6: 4 | T6: 2 | U6: 1 | V6: 3 | W6: 62 | X6: 1 | Y6: 8 | Z6: 106
A7: Go | B7: 45 | D7: K-nucleotide | E7: 9 | F7: 2 | G7: 24 | J7: 35 | M7: P4 | O7: 11 | P7: 2 | Q7: 7 | R7: 24 | S7: 3 | T7: 2 | V7: 2 | W7: 44 | Y7: 8 | Z7: 103
A8: Java | B8: 17 | D8: Mandelbrot | E8: 7 | F8: 4 | G8: 29 | J8: 40 | M8: Grand Total | N8: 2 | O8: 46 | P8: 3 | Q8: 30 | R8: 45 | S8: 17 | T8: 6 | U8: 1 | V8: 15 | W8: 215 | X8: 1 | Y8: 28 | Z8: 409
A9: JavaScript | B9: 6 | D9: N-body | E9: 13 | F9: 2 | G9: 17 | H9: 1 | J9: 33
A10: Julia | B10: 1 | D10: Pi-digits | E10: 17 | F10: 4 | G10: 19 | H10: 4 | J10: 44
A11: Python | B11: 215 | D11: Regex-redux | E11: 16 | F11: 3 | G11: 17 | H11: 8 | J11: 44 | M11: Count of SEARCH TYPE | N11: OUTPUT COMMENT
A12: Ruby | B12: 1 | D12: Reverse-complement | E12: 11 | G12: 20 | H12: 1 | I12: 4 | J12: 36 | M12: SEARCH TYPE | N12: Compiled ok. Wrong output. | O12: It did not compile. | P12: It worked. | Q12: Compile ok. Wrong output. | R12: Grand Total
A13: Rust | B13: 28 | D13: Spectral-norm | E13: 17 | F13: 1 | G13: 21 | J13: 39 | M13: Normal | N13: 72 | O13: 17 | P13: 112 | Q13: 2 | R13: 203
A14: Grand Total | B14: 394 | D14: Grand Total | E14: 130 | F14: 30 | G14: 230 | H14: 15 | I14: 4 | J14: 409 | M14: TBR | N14: 58 | O14: 13 | P14: 118 | Q14: 2 | R14: 191
M15: Grand Total | N15: 130 | O15: 30 | P15: 230 | Q15: 4 | R15: 394
D18: Count of OUTPUT COMMENT | F18: OUTPUT COMMENT | M18: Count of OUTPUT COMMENT | N18: OUTPUT COMMENT | O18: PROMPT
D19: BENCHMARK | E19: PROMPT | F19: Compiled ok. Wrong output. | G19: It did not compile. | H19: It worked. | I19: No Code | J19: Compile ok. Wrong output. | K19: Grand Total | N19: Compiled ok. Wrong output. | R19: Compiled ok. Wrong output. Total | S19: It did not compile. | W19: It did not compile. Total | X19: It worked. | AB19: It worked. Total | AC19: No Code | AG19: No Code Total | AH19: Compile ok. Wrong output. | AJ19: Compile ok. Wrong output. Total | AK19: Grand Total
D20: Binary-trees | E20: P1 | F20: 1 | G20: 4 | H20: 13 | K20: 18 | M20: BENCHMARK | N20: P1 | O20: P2 | P20: P3 | Q20: P4 | S20: P1 | T20: P2 | U20: P3 | V20: P4 | X20: P1 | Y20: P2 | Z20: P3 | AA20: P4 | AC20: P1 | AD20: P2 | AE20: P3 | AF20: P4 | AH20: P3 | AI20: P4
E21: P2 | F21: 1 | G21: 1 | H21: 8 | K21: 10 | M21: Binary-trees | N21: 1 | O21: 1 | P21: 3 | Q21: 3 | R21: 8 | S21: 4 | T21: 1 | U21: 1 | W21: 6 | X21: 13 | Y21: 8 | Z21: 10 | AA21: 16 | AB21: 47 | AK21: 61
E22: P3 | F22: 3 | G22: 1 | H22: 10 | K22: 14 | M22: Fannkuch-redux | N22: 7 | O22: 3 | P22: 8 | Q22: 9 | R22: 27 | S22: 2 | T22: 3 | U22: 1 | W22: 6 | X22: 3 | Y22: 4 | Z22: 2 | AA22: 1 | AB22: 10 | AD22: 1 | AG22: 1 | AK22: 44
E23: P4 | F23: 3 | H23: 16 | K23: 19 | M23: Fasta | O23: 1 | P23: 3 | Q23: 1 | R23: 5 | T23: 1 | U23: 1 | W23: 2 | X23: 8 | Y23: 6 | Z23: 5 | AA23: 7 | AB23: 26 | AK23: 33
D24: Binary-trees Total | F24: 8 | G24: 6 | H24: 47 | K24: 61 | M24: K-nucleotide | N24: 1 | O24: 5 | P24: 2 | Q24: 1 | R24: 9 | V24: 2 | W24: 2 | X24: 8 | Y24: 4 | Z24: 6 | AA24: 6 | AB24: 24 | AK24: 35
D25: Fannkuch-redux | E25: P1 | F25: 7 | G25: 2 | H25: 3 | K25: 12 | M25: Mandelbrot | P25: 6 | Q25: 1 | R25: 7 | S25: 1 | U25: 1 | V25: 2 | W25: 4 | X25: 10 | Y25: 9 | Z25: 5 | AA25: 5 | AB25: 29 | AK25: 40
E26: P2 | F26: 3 | G26: 3 | H26: 4 | I26: 1 | K26: 11 | M26: N-body | O26: 1 | P26: 7 | Q26: 5 | R26: 13 | S26: 2 | W26: 2 | X26: 6 | Y26: 7 | Z26: 1 | AA26: 3 | AB26: 17 | AE26: 1 | AG26: 1 | AK26: 33
E27: P3 | F27: 8 | G27: 1 | H27: 2 | K27: 11 | M27: Pi-digits | N27: 5 | O27: 1 | P27: 7 | Q27: 4 | R27: 17 | S27: 3 | T27: 1 | W27: 4 | X27: 6 | Y27: 5 | Z27: 4 | AA27: 4 | AB27: 19 | AC27: 2 | AD27: 2 | AG27: 4 | AK27: 44
E28: P4 | F28: 9 | H28: 1 | K28: 10 | M28: Regex-redux | N28: 4 | O28: 3 | P28: 5 | Q28: 4 | R28: 16 | T28: 2 | V28: 1 | W28: 3 | X28: 3 | Y28: 3 | Z28: 4 | AA28: 7 | AB28: 17 | AC28: 2 | AD28: 2 | AE28: 2 | AF28: 2 | AG28: 8 | AK28: 44
D29: Fannkuch-redux Total | F29: 27 | G29: 6 | H29: 10 | I29: 1 | K29: 44 | M29: Reverse-complement | N29: 1 | O29: 2 | P29: 5 | Q29: 3 | R29: 11 | X29: 7 | Y29: 6 | Z29: 3 | AA29: 4 | AB29: 20 | AC29: 1 | AG29: 1 | AH29: 2 | AI29: 2 | AJ29: 4 | AK29: 36
D30: Fasta | E30: P1 | H30: 8 | K30: 8 | M30: Spectral-norm | N30: 3 | O30: 2 | P30: 6 | Q30: 6 | R30: 17 | S30: 1 | W30: 1 | X30: 5 | Y30: 7 | Z30: 5 | AA30: 4 | AB30: 21 | AK30: 39
E31: P2 | F31: 1 | G31: 1 | H31: 6 | K31: 8 | M31: Grand Total | N31: 22 | O31: 19 | P31: 52 | Q31: 37 | R31: 130 | S31: 13 | T31: 8 | U31: 4 | V31: 5 | W31: 30 | X31: 69 | Y31: 59 | Z31: 45 | AA31: 57 | AB31: 230 | AC31: 5 | AD31: 5 | AE31: 3 | AF31: 2 | AG31: 15 | AH31: 2 | AI31: 2 | AJ31: 4 | AK31: 409
E32: P3 | F32: 3 | G32: 1 | H32: 5 | K32: 9
E33: P4 | F33: 1 | H33: 7 | K33: 8
D34: Fasta Total | F34: 5 | G34: 2 | H34: 26 | K34: 33 | M34: Count of OUTPUT COMMENT | O34: OUTPUT COMMENT
D35: K-nucleotide | E35: P1 | F35: 1 | H35: 8 | K35: 9 | M35: AI TOOL | N35: P. L. | O35: Compiled ok. Wrong output. | P35: It did not compile. | Q35: It worked. | R35: Compile ok. Wrong output. | S35: Grand Total
E36: P2 | F36: 5 | H36: 4 | K36: 9 | M36: ChatGPT | N36: C | O36: 7 | P36: 1 | Q36: 12 | S36: 20
E37: P3 | F37: 2 | H37: 6 | K37: 8 | N37: Go | O37: 2 | Q37: 13 | R37: 1 | S37: 16
E38: P4 | F38: 1 | G38: 2 | H38: 6 | K38: 9 | N38: Java | P38: 1 | S38: 1
D39: K-nucleotide Total | F39: 9 | G39: 2 | H39: 24 | K39: 35 | N39: Python | O39: 1 | Q39: 6 | S39: 7
D40: Mandelbrot | E40: P1 | G40: 1 | H40: 10 | K40: 11 | N40: Rust | O40: 3 | P40: 1 | Q40: 14 | R40: 3 | S40: 21
E41: P2 | H41: 9 | K41: 9 | M41: ChatGPT Total | O41: 13 | P41: 3 | Q41: 45 | R41: 4 | S41: 65
E42: P3 | F42: 6 | G42: 1 | H42: 5 | K42: 12 | M42: Claude | N42: C | O42: 6 | Q42: 9 | S42: 15
E43: P4 | F43: 1 | G43: 2 | H43: 5 | K43: 8 | N43: C# | Q43: 3 | S43: 3
...

Sheet correctness
A1: Search Mode | B1: Prompt | C1: Number of Codes Generated | D1: Number of Correct Codes | E1: Failed to compile or execute | F1: Compile ok. Wrong Output | G1: Correctness | H1: Total Correctness | I1: Correctness Difference
A2: Common | B2: P1 | C2: =COUNTIFS('all-data_locked'!$B$2:$B$410, "P1", 'all-data_locked'!$C$2:$C$410, "Normal", 'all-data_locked'!$E$2:$E$410, "<>No Code") -> 53 | D2: =COUNTIFS('all-data_locked'!$B$2:$B$410, "P1", 'all-data_locked'!$C$2:$C$410, "Normal", 'all-data_locked'!$F$2:$F$410, "It worked.") -> 35 | E2: =COUNTIFS('all-data_locked'!$B$2:$B$410, "P1", 'all-data_locked'!$C$2:$C$410, "Normal", 'all-data_locked'!$F$2:$F$410, "It did not compile.") -> 6 | F2: =COUNTIFS('all-data_locked'!$B$2:$B$410, "P1", 'all-data_locked'!$C$2:$C$410, "Normal", 'all-data_locked'!$F$2:$F$410, "Compiled ok. Wrong output.") -> 12 | G2: =(D2/C2)*100 -> 66.037736 | H2: =(SUM(D2:D5)/SUM(C2:C5))*100 -> 55.172414 | I2: =ABS(H2-H6) -> 6.6076909
B3: P2 | C3: =COUNTIFS('all-data_locked'!$B$2:$B$410, "P2", 'all-data_locked'!$C$2:$C$410, "Normal", 'all-data_locked'!$E$2:$E$410, "<>No Code") -> 42 | D3: =COUNTIFS('all-data_locked'!$B$2:$B$410, "P2", 'all-data_locked'!$C$2:$C$410, "Normal", 'all-data_locked'!$F$2:$F$410, "It worked.") -> 28 | E3: =COUNTIFS('all-data_locked'!$B$2:$B$410, "P2", 'all-data_locked'!$C$2:$C$410, "Normal", 'all-data_locked'!$F$2:$F$410, "It did not compile.") -> 5 | F3: =COUNTIFS('all-data_locked'!$B$2:$B$410, "P2", 'all-data_locked'!$C$2:$C$410, "Normal", 'all-data_locked'!$F$2:$F$410, "Compiled ok. Wrong output.") -> 9 | G3: =(D3/C3)*100 -> 66.666667
B4: P3 | C4: =COUNTIFS('all-data_locked'!$B$2:B$410, "P3", 'all-data_locked'!$C$2:$C$410, "Normal", 'all-data_locked'!$E$2:$E$410, "<>No Code") -> 54 | D4: =COUNTIFS('all-data_locked'!$B$2:$B$410, "P3", 'all-data_locked'!$C$2:$C$410, "Normal", 'all-data_locked'!$F$2:$F$410, "It worked.") -> 18 | E4: =COUNTIFS('all-data_locked'!$B$2:$B$410, "P3", 'all-data_locked'!$C$2:$C$410, "Normal", 'all-data_locked'!$F$2:$F$410, "It did not compile.") -> 3 | F4: =COUNTIFS('all-data_locked'!$B$2:$B$410, "P3", 'all-data_locked'!$C$2:$C$410, "Normal", 'all-data_locked'!$F$2:$F$410, "Compiled ok. Wrong output.") -> 33 | G4: =(D4/C4)*100 -> 33.333333
B5: P4 | C5: =COUNTIFS('all-data_locked'!$B$2:$B$410, "P4", 'all-data_locked'!$C$2:$C$410, "Normal", 'all-data_locked'!$E$2:$E$410, "<>No Code") -> 54 | D5: =COUNTIFS('all-data_locked'!$B$2:$B$410, "P4", 'all-data_locked'!$C$2:$C$410, "Normal", 'all-data_locked'!$F$2:$F$410, "It worked.") -> 31 | E5: =COUNTIFS('all-data_locked'!$B$2:$B$410, "P4", 'all-data_locked'!$C$2:$C$410, "Normal", 'all-data_locked'!$F$2:$F$410, "It did not compile.") -> 3 | F5: =COUNTIFS('all-data_locked'!$B$2:$B$410, "P4", 'all-data_locked'!$C$2:$C$410, "Normal", 'all-data_locked'!$F$2:$F$410, "Compiled ok. Wrong output.") -> 20 | G5: =(D5/C5)*100 -> 57.407407
A6: TBR | B6: P1 | C6: =COUNTIFS('all-data_locked'!$B$2:$B$410, "P1", 'all-data_locked'!$C$2:$C$410, "TBR", 'all-data_locked'!$E$2:$E$410, "<>No Code") -> 51 | D6: =COUNTIFS('all-data_locked'!$B$2:$B$410, "P1", 'all-data_locked'!$C$2:$C$410, "TBR", 'all-data_locked'!$F$2:$F$410, "It worked.") -> 34 | E6: =COUNTIFS('all-data_locked'!$B$2:$B$410, "P1", 'all-data_locked'!$C$2:$C$410, "TBR", 'all-data_locked'!$F$2:$F$410, "It did not compile.") -> 7 | F6: =COUNTIFS('all-data_locked'!$B$2:$B$410, "P1", 'all-data_locked'!$C$2:$C$410, "TBR", 'all-data_locked'!$F$2:$F$410, "Compiled ok. Wrong output.") -> 10 | G6: =(D6/C6)*100 -> 66.666667 | H6: =(SUM(D6:D9)/SUM(C6:C9))*100 -> 61.780105
B7: P2 | C7: =COUNTIFS('all-data_locked'!$B$2:$B$410, "P2", 'all-data_locked'!$C$2:$C$410, "TBR", 'all-data_locked'!$E$2:$E$410, "<>No Code") -> 44 | D7: =COUNTIFS('all-data_locked'!$B$2:$B$410, "P2", 'all-data_locked'!$C$2:$C$410, "TBR", 'all-data_locked'!$F$2:$F$410, "It worked.") -> 31 | E7: =COUNTIFS('all-data_locked'!$B$2:$B$410, "P2", 'all-data_locked'!$C$2:$C$410, "TBR", 'all-data_locked'!$F$2:$F$410, "It did not compile.") -> 3 | F7: =COUNTIFS('all-data_locked'!$B$2:$B$410, "P2", 'all-data_locked'!$C$2:$C$410, "TBR", 'all-data_locked'!$F$2:$F$410, "Compiled ok. Wrong output.") -> 10 | G7: =(D7/C7)*100 -> 70.454545
B8: P3 | C8: =COUNTIFS('all-data_locked'!$B$2:$B$410, "P3", 'all-data_locked'!$C$2:$C$410, "TBR", 'all-data_locked'!$E$2:$E$410, "<>No Code") -> 49 | D8: =COUNTIFS('all-data_locked'!$B$2:$B$410, "P3", 'all-data_locked'!$C$2:$C$410, "TBR", 'all-data_locked'!$F$2:$F$410, "It worked.") -> 27 | E8: =COUNTIFS('all-data_locked'!$B$2:$B$410, "P3", 'all-data_locked'!$C$2:$C$410, "TBR", 'all-data_locked'!$F$2:$F$410, "It did not compile.") -> 1 | F8: =COUNTIFS('all-data_locked'!$B$2:$B$410, "P3", 'all-data_locked'!$C$2:$C$410, "TBR", 'all-data_locked'!$F$2:$F$410, "Compiled ok. Wrong output.") -> 21 | G8: =(D8/C8)*100 -> 55.102041
B9: P4 | C9: =COUNTIFS('all-data_locked'!$B$2:$B$410, "P4", 'all-data_locked'!$C$2:$C$410, "TBR", 'all-data_locked'!$E$2:$E$410, "<>No Code") -> 47 | D9: =COUNTIFS('all-data_locked'!$B$2:$B$410, "P4", 'all-data_locked'!$C$2:$C$410, "TBR", 'all-data_locked'!$F$2:$F$410, "It worked.") -> 26 | E9: =COUNTIFS('all-data_locked'!$B$2:$B$410, "P4", 'all-data_locked'!$C$2:$C$410, "TBR", 'all-data_locked'!$F$2:$F$410, "It did not compile.") -> 2 | F9: =COUNTIFS('all-data_locked'!$B$2:$B$410, "P4", 'all-data_locked'!$C$2:$C$410, "TBR", 'all-data_locked'!$F$2:$F$410, "Compiled ok. Wrong output.") -> 19 | G9: =(D9/C9)*100 -> 55.319149
A11: AI-assistant | B11: Number of Codes Generated | C11: Number of Correct Codes | D11: Failed to compile or execute | E11: Compile ok. Wrong Output | F11: Correctness
A12: ChatGPT | B12: =COUNTIFS('all-data_locked'!$D$2:$D$410, "ChatGPT", 'all-data_locked'!$E$2:$E$410, "<>No Code") -> 65 | C12: =COUNTIFS('all-data_locked'!$D$2:$D$410, "ChatGPT", 'all-data_locked'!$F$2:$F$410, "It worked.") -> 45 | D12: =COUNTIFS('all-data_locked'!$D$2:$D$410, "ChatGPT", 'all-data_locked'!$F$2:$F$410, "It did not compile.") -> 3 | E12: =COUNTIFS('all-data_locked'!$D$2:$D$410, "ChatGPT", 'all-data_locked'!$F$2:$F$410, "Compiled ok. Wrong output.") -> 17 | F12: =(C12/B12)*100 -> 69.230769
A13: Claude | B13: =COUNTIFS('all-data_locked'!$D$2:$D$410, "Claude", 'all-data_locked'!$E$2:$E$410, "<>No Code") -> 115 | C13: =COUNTIFS('all-data_locked'!$D$2:$D$410, "Claude", 'all-data_locked'!$F$2:$F$410, "It worked.") -> 74 | D13: =COUNTIFS('all-data_locked'!$D$2:$D$410, "Claude", 'all-data_locked'!$F$2:$F$410, "It did not compile.") -> 4 | E13: =COUNTIFS('all-data_locked'!$D$2:$D$410, "Claude", 'all-data_locked'!$F$2:$F$410, "Compiled ok. Wrong output.") -> 37 | F13: =(C13/B13)*100 -> 64.347826
A14: DeepSeek | B14: =COUNTIFS('all-data_locked'!$D$2:$D$410, "DeepSeek", 'all-data_locked'!$E$2:$E$410, "<>No Code") -> 132 | C14: =COUNTIFS('all-data_locked'!$D$2:$D$410, "DeepSeek", 'all-data_locked'!$F$2:$F$410, "It worked.") -> 38 | D14: =COUNTIFS('all-data_locked'!$D$2:$D$410, "DeepSeek", 'all-data_locked'!$F$2:$F$410, "It did not compile.") -> 20 | E14: =COUNTIFS('all-data_locked'!$D$2:$D$410, "DeepSeek", 'all-data_locked'!$F$2:$F$410, "Compiled ok. Wrong output.") -> 74 | F14: =(C14/B14)*100 -> 28.787879
A15: Gemini | B15: =COUNTIFS('all-data_locked'!$D$2:$D$410, "Gemini", 'all-data_locked'!$E$2:$E$410, "<>No Code") -> 82 | C15: =COUNTIFS('all-data_locked'!$D$2:$D$410, "Gemini", 'all-data_locked'!$F$2:$F$410, "It worked.") -> 73 | D15: =COUNTIFS('all-data_locked'!$D$2:$D$410, "Gemini", 'all-data_locked'!$F$2:$F$410, "It did not compile.") -> 3 | E15: =COUNTIFS('all-data_locked'!$D$2:$D$410, "Gemini", 'all-data_locked'!$F$2:$F$410, "Compiled ok. Wrong output.") -> 6 | F15: =(C15/B15)*100 -> 89.02439
A17: Large Language Model | B17: Number of Codes Generated | C17: Number of Correct Codes | D17: Failed to compile or execute | E17: Compile ok. Wrong Output | F17: Correctness
A18: GPT 5.2 | B18: =COUNTIFS('all-data_locked'!$D$2:$D$410, "ChatGPT", 'all-data_locked'!$E$2:$E$410, "<>No Code") -> 65 | C18: =COUNTIFS('all-data_locked'!$D$2:$D$410, "ChatGPT", 'all-data_locked'!$F$2:$F$410, "It worked.") -> 45 | D18: =COUNTIFS('all-data_locked'!$D$2:$D$410, "ChatGPT", 'all-data_locked'!$F$2:$F$410, "It did not compile.") -> 3 | E18: =COUNTIFS('all-data_locked'!$D$2:$D$410, "ChatGPT", 'all-data_locked'!$F$2:$F$410, "Compiled ok. Wrong output.") -> 17 | F18: =(C18/B18)*100 -> 69.230769
A19: Sonnet 4.5 | B19: =COUNTIFS('all-data_locked'!$D$2:$D$410, "Claude", 'all-data_locked'!$E$2:$E$410, "<>No Code") -> 115 | C19: =COUNTIFS('all-data_locked'!$D$2:$D$410, "Claude", 'all-data_locked'!$F$2:$F$410, "It worked.") -> 74 | D19: =COUNTIFS('all-data_locked'!$D$2:$D$410, "Claude", 'all-data_locked'!$F$2:$F$410, "It did not compile.") -> 4 | E19: =COUNTIFS('all-data_locked'!$D$2:$D$410, "Claude", 'all-data_locked'!$F$2:$F$410, "Compiled ok. Wrong output.") -> 37 | F19: =(C19/B19)*100 -> 64.347826
A20: DeepSeek v3.2 | B20: =COUNTIFS('all-data_locked'!$D$2:$D$410, "DeepSeek", 'all-data_locked'!$E$2:$E$410, "<>No Code") -> 132 | C20: =COUNTIFS('all-data_locked'!$D$2:$D$410, "DeepSeek", 'all-data_locked'!$F$2:$F$410, "It worked.") -> 38 | D20: =COUNTIFS('all-data_locked'!$D$2:$D$410, "DeepSeek", 'all-data_locked'!$F$2:$F$410, "It did not compile.") -> 20 | E20: =COUNTIFS('all-data_locked'!$D$2:$D$410, "DeepSeek", 'all-data_locked'!$F$2:$F$410, "Compiled ok. Wrong output.") -> 74 | F20: =(C20/B20)*100 -> 28.787879
A21: Gemini 3.1 Pro | B21: =COUNTIFS('all-data_locked'!$D$2:$D$410, "Gemini", 'all-data_locked'!$E$2:$E$410, "<>No Code") -> 82 | C21: =COUNTIFS('all-data_locked'!$D$2:$D$410, "Gemini", 'all-data_locked'!$F$2:$F$410, "It worked.") -> 73 | D21: =COUNTIFS('all-data_locked'!$D$2:$D$410, "Gemini", 'all-data_locked'!$F$2:$F$410, "It did not compile.") -> 3 | E21: =COUNTIFS('all-data_locked'!$D$2:$D$410, "Gemini", 'all-data_locked'!$F$2:$F$410, "Compiled ok. Wrong output.") -> 6 | F21: =(C21/B21)*100 -> 89.02439

Sheet CV
A1: Benchmark | B1: P.L. | C1: M1 | D1: M2 | E1: M3 | F1: M4 | G1: M5 | H1: AVG | I1: STD | J1: CV
A2: binary-trees | B2: C CLBG | C2: 1.568 | D2: 1.561 | E2: 1.563 | F2: 1.559 | G2: 1.567 | H2: =AVERAGE(C2:G2) -> 1.5636 | I2: =STDEV(C2:G2) -> 0.0038470768 | J2: =(I2/H2)*100 -> 0.2460397 | L2: binary-trees | M2: C CLBG | N2: 3.2162847
A3: binary-trees | B3: Python | C3: 46.142 | D3: 43.891 | E3: 45.167 | F3: 45.975 | G3: 43.676 | H3: =AVERAGE(C3:G3) -> 44.9702 | I3: =STDEV(C3:G3) -> 1.1468538 | J3: =(I3/H3)*100 -> 2.5502529 | L3: binary-trees | M3: Python | N3: 2.5502529
A4: binary-trees | B4: Python CLBG | C4: 34.943 | D4: 33.494 | E4: 33.628 | F4: 33.446 | G4: 33.368 | H4: =AVERAGE(C4:G4) -> 33.7758 | I4: =STDEV(C4:G4) -> 0.65929523 | J4: =(I4/H4)*100 -> 1.9519752 | L4: binary-trees | M4: Python CLBG | N4: 1.9519752
A5: binary-trees | B5: C | C5: 1.153 | D5: 1.163 | E5: 1.144 | F5: 1.181 | G5: 1.181 | H5: =AVERAGE(C5:G5) -> 1.1644 | I5: =STDEV(C5:G5) -> 0.016577093 | J5: =(I5/H5)*100 -> 1.4236596 | L5: binary-trees | M5: C | N5: 1.4236596
A6: binary-trees | B6: Go | C6: 9.111 | D6: 9.248 | E6: 9.388 | F6: 9.34 | G6: 9.269 | H6: =AVERAGE(C6:G6) -> 9.2712 | I6: =STDEV(C6:G6) -> 0.1055732 | J6: =(I6/H6)*100 -> 1.138722 | L6: binary-trees | M6: Go | N6: 1.138722
A7: binary-trees | B7: Go CLBG | C7: 14.212 | D7: 14.239 | E7: 14.248 | F7: 14.352 | G7: 14.275 | H7: =AVERAGE(C7:G7) -> 14.2652 | I7: =STDEV(C7:G7) -> 0.053485512 | J7: =(I7/H7)*100 -> 0.37493699 | L7: binary-trees | M7: Go CLBG | N7: 0.37493699
A8: fannkuch-redux | B8: C | C8: 1.785 | D8: 1.745 | E8: 1.869 | F8: 1.752 | G8: 1.753 | H8: =AVERAGE(C8:G8) -> 1.7808 | I8: =STDEV(C8:G8) -> 0.051673978 | J8: =(I8/H8)*100 -> 2.9017283 | L8: fannkuch-redux | M8: C | N8: 2.9017283
