Workbook

Sheet Specs
B1: CHATGPT | C1: CLAUDE | D1: COPILOT | E1: DEEPSEEK | F1: GEMINI | G1: DATE CREATED
A2: pi-digits | B2: GPT 5.2 | C2: Sonnet 4.5 | D2: GPT 5.1 OpenAI O3 (TBR) | E2: DeepSeek v3.2 | F2: Gemini 3 Gemini 3 Pro (TBR) | G2: 25/01/2026
A3: n-body | G3: 26/01/2026
A4: reverse-complement | G4: 25/01/2026 | H4: Testar com os dados do CLBG e um exemplo de menor complexidade.
A5: fasta | G5: 23/01/2026
A6: k-nucleotide | G6: 25/01/2026
A7: regex-redux | G7: 25/01/2026
A8: spectral-norm | G8: 25/01/2026
A9: mandelbrot | G9: 26/01/2026
A10: binary-trees | G10: 26/01/2026
A11: fannkuch-redux | G11: 27/01/2026

Sheet all-data
A1: BENCHMARK | B1: PROMPT | C1: SEARCH TYPE | D1: AI TOOL | E1: P. L. | F1: OUTPUT COMMENT
A2: Fasta | B2: P1 | C2: Normal | D2: ChatGPT | E2: Python | F2: It worked.
A3: Fasta | B3: P1 | C3: Normal | D3: Claude | E3: Python | F3: It worked.
A4: Fasta | B4: P1 | C4: Normal | D4: Copilot | E4: Python | F4: It worked.
A5: Fasta | B5: P1 | C5: Normal | D5: DeepSeek | E5: Python | F5: It worked.
A6: Fasta | B6: P1 | C6: Normal | D6: Gemini | E6: Python | F6: It worked.
A7: Fasta | B7: P1 | C7: TBR | D7: ChatGPT | E7: Python | F7: It worked.
A8: Fasta | B8: P1 | C8: TBR | D8: Claude | E8: Python | F8: It worked.
A9: Fasta | B9: P1 | C9: TBR | D9: Copilot | E9: Python | F9: Compiled ok. Wrong output.
A10: Fasta | B10: P1 | C10: TBR | D10: DeepSeek | E10: Python | F10: It worked.
A11: Fasta | B11: P1 | C11: TBR | D11: Gemini | E11: Python | F11: It worked.
A12: Fasta | B12: P2 | C12: Normal | D12: ChatGPT | E12: Go | F12: It worked.
... A499: Fannkuch-redux | B499: P4 | C499: TBR | D499: Gemini | E499: C++ | F499: Compiled ok. Wrong output.

Sheet Recurrence
A2: P. L. | B2: Count of P. L. | D2: Count of OUTPUT COMMENT | E2: OUTPUT COMMENT | M2: Count of P. L. | N2: P. L.
A3: Bash (.sh) | B3: 2 | D3: BENCHMARK | E3: Compiled ok. Wrong output. | F3: It did not compile. | G3: It worked. | H3: No Code | I3: Grand Total | M3: PROMPT | N3: Bash (.sh) | O3: C | P3: C# | Q3: C++ | R3: Go | S3: Java | T3: JavaScript | U3: Julia | V3: Python | W3: Ruby | X3: Rust | Y3: Grand Total
A4: C | B4: 60 | D4: Binary-trees | E4: 8 | F4: 11 | G4: 50 | H4: 2 | I4: 71 | M4: P1 | N4: 1 | O4: 16 | P4: 1 | Q4: 5 | R4: 3 | S4: 12 | T4: 2 | V4: 81 | X4: 5 | Y4: 126
A5: C# | B5: 3 | D5: Fannkuch-redux | E5: 36 | F5: 7 | G5: 4 | H5: 6 | I5: 53 | M5: P2 | N5: 1 | O5: 15 | Q5: 14 | R5: 10 | S5: 1 | V5: 51 | X5: 8 | Y5: 100
A6: C++ | B6: 38 | D6: Fasta | E6: 8 | F6: 1 | G6: 31 | H6: 1 | I6: 41 | M6: P3 | O6: 15 | Q6: 9 | R6: 5 | S6: 5 | T6: 2 | U6: 1 | V6: 70 | W6: 1 | X6: 10 | Y6: 118
A7: Go | B7: 39 | D7: K-nucleotide | E7: 16 | F7: 4 | G7: 21 | H7: 4 | I7: 45 | M7: P4 | O7: 14 | P7: 2 | Q7: 10 | R7: 21 | S7: 7 | T7: 2 | V7: 54 | X7: 8 | Y7: 118
A8: Java | B8: 25 | D8: Mandelbrot | E8: 8 | F8: 7 | G8: 32 | H8: 1 | I8: 48 | M8: Grand Total | N8: 2 | O8: 60 | P8: 3 | Q8: 38 | R8: 39 | S8: 25 | T8: 6 | U8: 1 | V8: 256 | W8: 1 | X8: 31 | Y8: 462
A9: JavaScript | B9: 6 | D9: N-body | E9: 15 | F9: 2 | G9: 21 | H9: 4 | I9: 42
A10: Julia | B10: 1 | D10: Pi-digits | E10: 24 | F10: 5 | G10: 19 | H10: 4 | I10: 52
A11: Python | B11: 256 | D11: Regex-redux | E11: 21 | F11: 6 | G11: 15 | H11: 10 | I11: 52 | M11: Count of SEARCH TYPE | N11: OUTPUT COMMENT
A12: Ruby | B12: 1 | D12: Reverse-complement | E12: 29 | G12: 15 | H12: 3 | I12: 47 | M12: SEARCH TYPE | N12: Compiled ok. Wrong output. | O12: It did not compile. | P12: It worked. | Q12: Grand Total
A13: Rust | B13: 31 | D13: Spectral-norm | E13: 21 | F13: 1 | G13: 24 | H13: 1 | I13: 47 | M13: Normal | N13: 100 | O13: 20 | P13: 115 | Q13: 235
A14: Grand Total | B14: 462 | D14: Grand Total | E14: 186 | F14: 44 | G14: 232 | H14: 36 | I14: 498 | M14: TBR | N14: 86 | O14: 24 | P14: 117 | Q14: 227
M15: Grand Total | N15: 186 | O15: 44 | P15: 232 | Q15: 462
D18: Count of OUTPUT COMMENT | F18: OUTPUT COMMENT | M18: Count of OUTPUT COMMENT | N18: OUTPUT COMMENT | O18: PROMPT
D19: BENCHMARK | E19: PROMPT | F19: Compiled ok. Wrong output. | G19: It did not compile. | H19: It worked. | I19: No Code | J19: Grand Total | N19: Compiled ok. Wrong output. | R19: Compiled ok. Wrong output. Total | S19: It did not compile. | W19: It did not compile. Total | X19: It worked. | AB19: It worked. Total | AC19: No Code | AG19: No Code Total | AH19: Grand Total
D20: Binary-trees | E20: P3 | F20: 3 | H20: 12 | I20: 1 | J20: 16 | M20: BENCHMARK | N20: P1 | O20: P2 | P20: P3 | Q20: P4 | S20: P1 | T20: P2 | U20: P3 | V20: P4 | X20: P1 | Y20: P2 | Z20: P3 | AA20: P4 | AC20: P1 | AD20: P2 | AE20: P3 | AF20: P4
E21: P4 | F21: 3 | H21: 18 | J21: 21 | M21: Binary-trees | N21: 1 | O21: 1 | P21: 3 | Q21: 3 | R21: 8 | S21: 8 | T21: 3 | W21: 11 | X21: 13 | Y21: 7 | Z21: 12 | AA21: 18 | AB21: 50 | AD21: 1 | AE21: 1 | AG21: 2 | AH21: 71
D22: Binary-trees Total | F22: 6 | H22: 30 | I22: 1 | J22: 37 | M22: Fannkuch-redux | N22: 9 | O22: 4 | P22: 12 | Q22: 11 | R22: 36 | S22: 3 | T22: 3 | U22: 1 | W22: 7 | X22: 1 | Y22: 3 | AB22: 4 | AC22: 1 | AD22: 3 | AE22: 1 | AF22: 1 | AG22: 6 | AH22: 53
D23: Fannkuch-redux | E23: P3 | F23: 12 | G23: 1 | I23: 1 | J23: 14 | M23: Fasta | N23: 1 | O23: 1 | P23: 4 | Q23: 2 | R23: 8 | T23: 1 | W23: 1 | X23: 9 | Y23: 8 | Z23: 6 | AA23: 8 | AB23: 31 | AE23: 1 | AG23: 1 | AH23: 41
E24: P4 | F24: 11 | I24: 1 | J24: 12 | M24: K-nucleotide | N24: 4 | O24: 7 | P24: 4 | Q24: 1 | R24: 16 | T24: 1 | U24: 1 | V24: 2 | W24: 4 | X24: 7 | Y24: 3 | Z24: 5 | AA24: 6 | AB24: 21 | AD24: 1 | AE24: 1 | AF24: 2 | AG24: 4 | AH24: 45
D25: Fannkuch-redux Total | F25: 23 | G25: 1 | I25: 2 | J25: 26 | M25: Mandelbrot | P25: 7 | Q25: 1 | R25: 8 | S25: 1 | U25: 2 | V25: 4 | W25: 7 | X25: 12 | Y25: 10 | Z25: 5 | AA25: 5 | AB25: 32 | AD25: 1 | AG25: 1 | AH25: 48
D26: Fasta | E26: P3 | F26: 4 | H26: 6 | I26: 1 | J26: 11 | M26: N-body | O26: 1 | P26: 7 | Q26: 7 | R26: 15 | S26: 2 | W26: 2 | X26: 7 | Y26: 8 | Z26: 2 | AA26: 4 | AB26: 21 | AC26: 1 | AD26: 1 | AE26: 2 | AG26: 4 | AH26: 42
E27: P4 | F27: 2 | H27: 8 | J27: 10 | M27: Pi-digits | N27: 6 | O27: 2 | P27: 10 | Q27: 6 | R27: 24 | S27: 3 | T27: 2 | W27: 5 | X27: 7 | Y27: 5 | Z27: 3 | AA27: 4 | AB27: 19 | AC27: 2 | AD27: 2 | AG27: 4 | AH27: 52
D28: Fasta Total | F28: 6 | H28: 14 | I28: 1 | J28: 21 | M28: Regex-redux | N28: 6 | O28: 4 | P28: 6 | Q28: 5 | R28: 21 | T28: 4 | V28: 2 | W28: 6 | X28: 2 | Y28: 2 | Z28: 4 | AA28: 7 | AB28: 15 | AC28: 3 | AD28: 2 | AE28: 3 | AF28: 2 | AG28: 10 | AH28: 52
D29: K-nucleotide | E29: P3 | F29: 4 | G29: 1 | H29: 5 | I29: 1 | J29: 11 | M29: Reverse-complement | N29: 7 | O29: 5 | P29: 10 | Q29: 7 | R29: 29 | X29: 6 | Y29: 4 | Z29: 2 | AA29: 3 | AB29: 15 | AC29: 1 | AD29: 1 | AF29: 1 | AG29: 3 | AH29: 47
E30: P4 | F30: 1 | G30: 2 | H30: 6 | I30: 2 | J30: 11 | M30: Spectral-norm | N30: 4 | O30: 3 | P30: 8 | Q30: 6 | R30: 21 | S30: 1 | W30: 1 | X30: 6 | Y30: 8 | Z30: 4 | AA30: 6 | AB30: 24 | AC30: 1 | AG30: 1 | AH30: 47
D31: K-nucleotide Total | F31: 5 | G31: 3 | H31: 11 | I31: 3 | J31: 22 | M31: Grand Total | N31: 38 | O31: 28 | P31: 71 | Q31: 49 | R31: 186 | S31: 18 | T31: 14 | U31: 4 | V31: 8 | W31: 44 | X31: 70 | Y31: 58 | Z31: 43 | AA31: 61 | AB31: 232 | AC31: 9 | AD31: 12 | AE31: 9 | AF31: 6 | AG31: 36 | AH31: 498
D32: Mandelbrot | E32: P3 | F32: 7 | G32: 2 | H32: 5 | J32: 14
E33: P4 | F33: 1 | G33: 4 | H33: 5 | J33: 10
D34: Mandelbrot Total | F34: 8 | G34: 6 | H34: 10 | J34: 24 | M34: Count of OUTPUT COMMENT | O34: OUTPUT COMMENT
D35: N-body | E35: P3 | F35: 7 | H35: 2 | I35: 2 | J35: 11 | M35: AI TOOL | N35: P. L. | O35: Compiled ok. Wrong output. | P35: It did not compile. | Q35: It worked. | R35: Grand Total
E36: P4 | F36: 7 | H36: 4 | J36: 11 | M36: ChatGPT | N36: C | O36: 7 | P36: 1 | Q36: 12 | R36: 20
D37: N-body Total | F37: 14 | H37: 6 | I37: 2 | J37: 22 | N37: Go | O37: 3 | Q37: 13 | R37: 16
D38: Pi-digits | E38: P3 | F38: 10 | H38: 3 | J38: 13 | N38: Java | P38: 1 | R38: 1
E39: P4 | F39: 6 | H39: 4 | J39: 10 | N39: Python | O39: 1 | Q39: 5 | R39: 6
D40: Pi-digits Total | F40: 16 | H40: 7 | J40: 23 | N40: Rust | O40: 6 | P40: 1 | Q40: 15 | R40: 22
D41: Regex-redux | E41: P3 | F41: 6 | H41: 4 | I41: 3 | J41: 13 | M41: ChatGPT Total | O41: 17 | P41: 3 | Q41: 45 | R41: 65
E42: P4 | F42: 5 | G42: 2 | H42: 7 | I42: 2 | J42: 16 | M42: Claude | N42: C | O42: 6 | Q42: 9 | R42: 15
D43: Regex-redux Total | F43: 11 | G43: 2 | H43: 11 | I43: 5 | J43: 29 | N43: C# | Q43: 3 | R43: 3
...

Sheet correctness
A1: Search Mode | B1: Prompt | C1: Number of Codes Generated | D1: Number of Correct Codes | E1: Failed to compile or execute | F1: Compile ok. Wrong Output | G1: Correctness | H1: Total Correctness | I1: Correctness Difference
A2: Common | B2: P1 | C2: =COUNTIFS('all-data'!$B$2:$B$499, "P1", 'all-data'!$C$2:$C$499, "Normal", 'all-data'!$E$2:$E$499, "<>No Code") -> 64 | D2: =COUNTIFS('all-data'!$B$2:$B$499, "P1", 'all-data'!$C$2:$C$499, "Normal", 'all-data'!$F$2:$F$499, "It worked.") -> 36 | E2: =COUNTIFS('all-data'!$B$2:$B$499, "P1", 'all-data'!$C$2:$C$499, "Normal", 'all-data'!$F$2:$F$499, "It did not compile.") -> 8 | F2: =COUNTIFS('all-data'!$B$2:$B$499, "P1", 'all-data'!$C$2:$C$499, "Normal", 'all-data'!$F$2:$F$499, "Compiled ok. Wrong output.") -> 20 | G2: =(D2/C2)*100 -> 56.25 | H2: =(SUM(D2:D5)/SUM(C2:C5))*100 -> 48.93617 | I2: =ABS(H2-H6) -> 2.60568
B3: P2 | C3: =COUNTIFS('all-data'!$B$2:$B$499, "P2", 'all-data'!$C$2:$C$499, "Normal", 'all-data'!$E$2:$E$499, "<>No Code") -> 51 | D3: =COUNTIFS('all-data'!$B$2:$B$499, "P2", 'all-data'!$C$2:$C$499, "Normal", 'all-data'!$F$2:$F$499, "It worked.") -> 31 | E3: =COUNTIFS('all-data'!$B$2:$B$499, "P2", 'all-data'!$C$2:$C$499, "Normal", 'all-data'!$F$2:$F$499, "It did not compile.") -> 6 | F3: =COUNTIFS('all-data'!$B$2:$B$499, "P2", 'all-data'!$C$2:$C$499, "Normal", 'all-data'!$F$2:$F$499, "Compiled ok. Wrong output.") -> 14 | G3: =(D3/C3)*100 -> 60.784314
B4: P3 | C4: =COUNTIFS('all-data'!$B$2:B$499, "P3", 'all-data'!$C$2:$C$499, "Normal", 'all-data'!$E$2:$E$499, "<>No Code") -> 58 | D4: =COUNTIFS('all-data'!$B$2:$B$499, "P3", 'all-data'!$C$2:$C$499, "Normal", 'all-data'!$F$2:$F$499, "It worked.") -> 17 | E4: =COUNTIFS('all-data'!$B$2:$B$499, "P3", 'all-data'!$C$2:$C$499, "Normal", 'all-data'!$F$2:$F$499, "It did not compile.") -> 2 | F4: =COUNTIFS('all-data'!$B$2:$B$499, "P3", 'all-data'!$C$2:$C$499, "Normal", 'all-data'!$F$2:$F$499, "Compiled ok. Wrong output.") -> 39 | G4: =(D4/C4)*100 -> 29.310345
B5: P4 | C5: =COUNTIFS('all-data'!$B$2:$B$499, "P4", 'all-data'!$C$2:$C$499, "Normal", 'all-data'!$E$2:$E$499, "<>No Code") -> 62 | D5: =COUNTIFS('all-data'!$B$2:$B$499, "P4", 'all-data'!$C$2:$C$499, "Normal", 'all-data'!$F$2:$F$499, "It worked.") -> 31 | E5: =COUNTIFS('all-data'!$B$2:$B$499, "P4", 'all-data'!$C$2:$C$499, "Normal", 'all-data'!$F$2:$F$499, "It did not compile.") -> 4 | F5: =COUNTIFS('all-data'!$B$2:$B$499, "P4", 'all-data'!$C$2:$C$499, "Normal", 'all-data'!$F$2:$F$499, "Compiled ok. Wrong output.") -> 27 | G5: =(D5/C5)*100 -> 50
A6: TBR | B6: P1 | C6: =COUNTIFS('all-data'!$B$2:$B$499, "P1", 'all-data'!$C$2:$C$499, "TBR", 'all-data'!$E$2:$E$499, "<>No Code") -> 62 | D6: =COUNTIFS('all-data'!$B$2:$B$499, "P1", 'all-data'!$C$2:$C$499, "TBR", 'all-data'!$F$2:$F$499, "It worked.") -> 34 | E6: =COUNTIFS('all-data'!$B$2:$B$499, "P1", 'all-data'!$C$2:$C$499, "TBR", 'all-data'!$F$2:$F$499, "It did not compile.") -> 10 | F6: =COUNTIFS('all-data'!$B$2:$B$499, "P1", 'all-data'!$C$2:$C$499, "TBR", 'all-data'!$F$2:$F$499, "Compiled ok. Wrong output.") -> 18 | G6: =(D6/C6)*100 -> 54.83871 | H6: =(SUM(D6:D9)/SUM(C6:C9))*100 -> 51.54185
B7: P2 | C7: =COUNTIFS('all-data'!$B$2:$B$499, "P2", 'all-data'!$C$2:$C$499, "TBR", 'all-data'!$E$2:$E$499, "<>No Code") -> 49 | D7: =COUNTIFS('all-data'!$B$2:$B$499, "P2", 'all-data'!$C$2:$C$499, "TBR", 'all-data'!$F$2:$F$499, "It worked.") -> 27 | E7: =COUNTIFS('all-data'!$B$2:$B$499, "P2", 'all-data'!$C$2:$C$499, "TBR", 'all-data'!$F$2:$F$499, "It did not compile.") -> 8 | F7: =COUNTIFS('all-data'!$B$2:$B$499, "P2", 'all-data'!$C$2:$C$499, "TBR", 'all-data'!$F$2:$F$499, "Compiled ok. Wrong output.") -> 14 | G7: =(D7/C7)*100 -> 55.102041
B8: P3 | C8: =COUNTIFS('all-data'!$B$2:$B$499, "P3", 'all-data'!$C$2:$C$499, "TBR", 'all-data'!$E$2:$E$499, "<>No Code") -> 60 | D8: =COUNTIFS('all-data'!$B$2:$B$499, "P3", 'all-data'!$C$2:$C$499, "TBR", 'all-data'!$F$2:$F$499, "It worked.") -> 26 | E8: =COUNTIFS('all-data'!$B$2:$B$499, "P3", 'all-data'!$C$2:$C$499, "TBR", 'all-data'!$F$2:$F$499, "It did not compile.") -> 2 | F8: =COUNTIFS('all-data'!$B$2:$B$499, "P3", 'all-data'!$C$2:$C$499, "TBR", 'all-data'!$F$2:$F$499, "Compiled ok. Wrong output.") -> 32 | G8: =(D8/C8)*100 -> 43.333333
B9: P4 | C9: =COUNTIFS('all-data'!$B$2:$B$499, "P4", 'all-data'!$C$2:$C$499, "TBR", 'all-data'!$E$2:$E$499, "<>No Code") -> 56 | D9: =COUNTIFS('all-data'!$B$2:$B$499, "P4", 'all-data'!$C$2:$C$499, "TBR", 'all-data'!$F$2:$F$499, "It worked.") -> 30 | E9: =COUNTIFS('all-data'!$B$2:$B$499, "P4", 'all-data'!$C$2:$C$499, "TBR", 'all-data'!$F$2:$F$499, "It did not compile.") -> 4 | F9: =COUNTIFS('all-data'!$B$2:$B$499, "P4", 'all-data'!$C$2:$C$499, "TBR", 'all-data'!$F$2:$F$499, "Compiled ok. Wrong output.") -> 22 | G9: =(D9/C9)*100 -> 53.571429
A11: AI-assistant | B11: Number of Codes Generated | C11: Number of Correct Codes | D11: Failed to compile or execute | E11: Compile ok. Wrong Output | F11: Correctness
A12: ChatGPT | B12: =COUNTIFS('all-data'!$D$2:$D$499, "ChatGPT", 'all-data'!$E$2:$E$499, "<>No Code") -> 65 | C12: =COUNTIFS('all-data'!$D$2:$D$499, "ChatGPT", 'all-data'!$F$2:$F$499, "It worked.") -> 45 | D12: =COUNTIFS('all-data'!$D$2:$D$499, "ChatGPT", 'all-data'!$F$2:$F$499, "It did not compile.") -> 3 | E12: =COUNTIFS('all-data'!$D$2:$D$499, "ChatGPT", 'all-data'!$F$2:$F$499, "Compiled ok. Wrong output.") -> 17 | F12: =(C12/B12)*100 -> 69.230769
A13: Claude | B13: =COUNTIFS('all-data'!$D$2:$D$499, "Claude", 'all-data'!$E$2:$E$499, "<>No Code") -> 115 | C13: =COUNTIFS('all-data'!$D$2:$D$499, "Claude", 'all-data'!$F$2:$F$499, "It worked.") -> 74 | D13: =COUNTIFS('all-data'!$D$2:$D$499, "Claude", 'all-data'!$F$2:$F$499, "It did not compile.") -> 4 | E13: =COUNTIFS('all-data'!$D$2:$D$499, "Claude", 'all-data'!$F$2:$F$499, "Compiled ok. Wrong output.") -> 37 | F13: =(C13/B13)*100 -> 64.347826
A14: Microsoft Copilot | B14: =COUNTIFS('all-data'!$D$2:$D$499, "Copilot", 'all-data'!$E$2:$E$499, "<>No Code") -> 68 | C14: =COUNTIFS('all-data'!$D$2:$D$499, "Copilot", 'all-data'!$F$2:$F$499, "It worked.") -> 24 | D14: =COUNTIFS('all-data'!$D$2:$D$499, "Copilot", 'all-data'!$F$2:$F$499, "It did not compile.") -> 7 | E14: =COUNTIFS('all-data'!$D$2:$D$499, "Copilot", 'all-data'!$F$2:$F$499, "Compiled ok. Wrong output.") -> 37 | F14: =(C14/B14)*100 -> 35.294118
A15: DeepSeek | B15: =COUNTIFS('all-data'!$D$2:$D$499, "DeepSeek", 'all-data'!$E$2:$E$499, "<>No Code") -> 132 | C15: =COUNTIFS('all-data'!$D$2:$D$499, "DeepSeek", 'all-data'!$F$2:$F$499, "It worked.") -> 38 | D15: =COUNTIFS('all-data'!$D$2:$D$499, "DeepSeek", 'all-data'!$F$2:$F$499, "It did not compile.") -> 20 | E15: =COUNTIFS('all-data'!$D$2:$D$499, "DeepSeek", 'all-data'!$F$2:$F$499, "Compiled ok. Wrong output.") -> 74 | F15: =(C15/B15)*100 -> 28.787879
A16: Gemini | B16: =COUNTIFS('all-data'!$D$2:$D$499, "Gemini", 'all-data'!$E$2:$E$499, "<>No Code") -> 82 | C16: =COUNTIFS('all-data'!$D$2:$D$499, "Gemini", 'all-data'!$F$2:$F$499, "It worked.") -> 51 | D16: =COUNTIFS('all-data'!$D$2:$D$499, "Gemini", 'all-data'!$F$2:$F$499, "It did not compile.") -> 10 | E16: =COUNTIFS('all-data'!$D$2:$D$499, "Gemini", 'all-data'!$F$2:$F$499, "Compiled ok. Wrong output.") -> 21 | F16: =(C16/B16)*100 -> 62.195122
A18: Large Language Model | B18: Number of Codes Generated | C18: Number of Correct Codes | D18: Failed to compile or execute | E18: Compile ok. Wrong Output | F18: Correctness
A19: GPT 5.2 | B19: =COUNTIFS('all-data'!$D$2:$D$499, "ChatGPT", 'all-data'!$E$2:$E$499, "<>No Code") -> 65 | C19: =COUNTIFS('all-data'!$D$2:$D$499, "ChatGPT", 'all-data'!$F$2:$F$499, "It worked.") -> 45 | D19: =COUNTIFS('all-data'!$D$2:$D$499, "ChatGPT", 'all-data'!$F$2:$F$499, "It did not compile.") -> 3 | E19: =COUNTIFS('all-data'!$D$2:$D$499, "ChatGPT", 'all-data'!$F$2:$F$499, "Compiled ok. Wrong output.") -> 17 | F19: =(C19/B19)*100 -> 69.230769
A20: Sonnet 4.5 | B20: =COUNTIFS('all-data'!$D$2:$D$499, "Claude", 'all-data'!$E$2:$E$499, "<>No Code") -> 115 | C20: =COUNTIFS('all-data'!$D$2:$D$499, "Claude", 'all-data'!$F$2:$F$499, "It worked.") -> 74 | D20: =COUNTIFS('all-data'!$D$2:$D$499, "Claude", 'all-data'!$F$2:$F$499, "It did not compile.") -> 4 | E20: =COUNTIFS('all-data'!$D$2:$D$499, "Claude", 'all-data'!$F$2:$F$499, "Compiled ok. Wrong output.") -> 37 | F20: =(C20/B20)*100 -> 64.347826
A21: GPT 5.1 | B21: =COUNTIFS('all-data'!$D$2:$D$499, "Copilot", 'all-data'!$C$2:$C$499, "Normal", 'all-data'!$E$2:$E$499, "<>No Code") -> 33 | C21: =COUNTIFS('all-data'!$D$2:$D$499, "Copilot", 'all-data'!$C$2:$C$499, "Normal", 'all-data'!$F$2:$F$499, "It worked.") -> 14 | D21: =COUNTIFS('all-data'!$D$2:$D$499, "Copilot", 'all-data'!$C$2:$C$499, "Normal", 'all-data'!$F$2:$F$499, "It did not compile.") -> 2 | E21: =COUNTIFS('all-data'!$D$2:$D$499, "Copilot", 'all-data'!$C$2:$C$499, "Normal", 'all-data'!$F$2:$F$499, "Compiled ok. Wrong output.") -> 17 | F21: =(C21/B21)*100 -> 42.424242
A22: OpenAI O3 | B22: =COUNTIFS('all-data'!$D$2:$D$499, "Copilot", 'all-data'!$C$2:$C$499, "TBR", 'all-data'!$C$2:$C$499, "TBR", 'all-data'!$E$2:$E$499, "<>No Code") -> 35 | C22: =COUNTIFS('all-data'!$D$2:$D$499, "Copilot", 'all-data'!$C$2:$C$499, "TBR", 'all-data'!$F$2:$F$499, "It worked.") -> 10 | D22: =COUNTIFS('all-data'!$D$2:$D$499, "Copilot", 'all-data'!$C$2:$C$499, "TBR", 'all-data'!$F$2:$F$499, "It did not compile.") -> 5 | E22: =COUNTIFS('all-data'!$D$2:$D$499, "Copilot", 'all-data'!$C$2:$C$499, "TBR", 'all-data'!$F$2:$F$499, "Compiled ok. Wrong output.") -> 20 | F22: =(C22/B22)*100 -> 28.571429
A23: DeepSeek v3.2 | B23: =COUNTIFS('all-data'!$D$2:$D$499, "DeepSeek", 'all-data'!$E$2:$E$499, "<>No Code") -> 132 | C23: =COUNTIFS('all-data'!$D$2:$D$499, "DeepSeek", 'all-data'!$F$2:$F$499, "It worked.") -> 38 | D23: =COUNTIFS('all-data'!$D$2:$D$499, "DeepSeek", 'all-data'!$F$2:$F$499, "It did not compile.") -> 20 | E23: =COUNTIFS('all-data'!$D$2:$D$499, "DeepSeek", 'all-data'!$F$2:$F$499, "Compiled ok. Wrong output.") -> 74 | F23: =(C23/B23)*100 -> 28.787879
A24: Gemini 3 | B24: =COUNTIFS('all-data'!$D$2:$D$499, "Gemini", 'all-data'!$C$2:$C$499, "Normal", 'all-data'!$E$2:$E$499, "<>No Code") -> 39 | C24: =COUNTIFS('all-data'!$D$2:$D$499, "Gemini", 'all-data'!$C$2:$C$499, "Normal", 'all-data'!$F$2:$F$499, "It worked.") -> 24 | D24: =COUNTIFS('all-data'!$D$2:$D$499, "Gemini", 'all-data'!$C$2:$C$499, "Normal", 'all-data'!$F$2:$F$499, "It did not compile.") -> 3 | E24: =COUNTIFS('all-data'!$D$2:$D$499, "Gemini", 'all-data'!$C$2:$C$499, "Normal", 'all-data'!$F$2:$F$499, "Compiled ok. Wrong output.") -> 12 | F24: =(C24/B24)*100 -> 61.538462
A25: Gemini 3 Pro | B25: =COUNTIFS('all-data'!$D$2:$D$499, "Gemini", 'all-data'!$C$2:$C$499, "TBR", 'all-data'!$E$2:$E$499, "<>No Code") -> 43 | C25: =COUNTIFS('all-data'!$D$2:$D$499, "Gemini", 'all-data'!$C$2:$C$499, "TBR", 'all-data'!$F$2:$F$499, "It worked.") -> 27 | D25: =COUNTIFS('all-data'!$D$2:$D$499, "Gemini", 'all-data'!$C$2:$C$499, "TBR", 'all-data'!$F$2:$F$499, "It did not compile.") -> 7 | E25: =COUNTIFS('all-data'!$D$2:$D$499, "Gemini", 'all-data'!$C$2:$C$499, "TBR", 'all-data'!$F$2:$F$499, "Compiled ok. Wrong output.") -> 9 | F25: =(C25/B25)*100 -> 62.790698

Sheet CV
A1: Benchmark | B1: P.L. | C1: M1 | D1: M2 | E1: M3 | F1: M4 | G1: M5 | H1: AVG | I1: STD | J1: CV
A2: binary-trees | B2: C CLBG | C2: 1.568 | D2: 1.561 | E2: 1.563 | F2: 1.559 | G2: 1.567 | H2: =AVERAGE(C2:G2) -> 1.5636 | I2: =STDEV(C2:G2) -> 0.0038470768 | J2: =(I2/H2)*100 -> 0.2460397 | L2: binary-trees | M2: C CLBG | N2: 3.2162847
A3: binary-trees | B3: Python | C3: 46.142 | D3: 43.891 | E3: 45.167 | F3: 45.975 | G3: 43.676 | H3: =AVERAGE(C3:G3) -> 44.9702 | I3: =STDEV(C3:G3) -> 1.1468538 | J3: =(I3/H3)*100 -> 2.5502529 | L3: binary-trees | M3: Python | N3: 2.5502529
A4: binary-trees | B4: Python CLBG | C4: 34.943 | D4: 33.494 | E4: 33.628 | F4: 33.446 | G4: 33.368 | H4: =AVERAGE(C4:G4) -> 33.7758 | I4: =STDEV(C4:G4) -> 0.65929523 | J4: =(I4/H4)*100 -> 1.9519752 | L4: binary-trees | M4: Python CLBG | N4: 1.9519752
A5: binary-trees | B5: C | C5: 1.153 | D5: 1.163 | E5: 1.144 | F5: 1.181 | G5: 1.181 | H5: =AVERAGE(C5:G5) -> 1.1644 | I5: =STDEV(C5:G5) -> 0.016577093 | J5: =(I5/H5)*100 -> 1.4236596 | L5: binary-trees | M5: C | N5: 1.4236596
A6: binary-trees | B6: Go | C6: 9.111 | D6: 9.248 | E6: 9.388 | F6: 9.34 | G6: 9.269 | H6: =AVERAGE(C6:G6) -> 9.2712 | I6: =STDEV(C6:G6) -> 0.1055732 | J6: =(I6/H6)*100 -> 1.138722 | L6: binary-trees | M6: Go | N6: 1.138722
A7: binary-trees | B7: Go CLBG | C7: 14.212 | D7: 14.239 | E7: 14.248 | F7: 14.352 | G7: 14.275 | H7: =AVERAGE(C7:G7) -> 14.2652 | I7: =STDEV(C7:G7) -> 0.053485512 | J7: =(I7/H7)*100 -> 0.37493699 | L7: binary-trees | M7: Go CLBG | N7: 0.37493699
A8: fannkuch-redux | B8: C | C8: 1.785 | D8: 1.745 | E8: 1.869 | F8: 1.752 | G8: 1.753 | H8: =AVERAGE(C8:G8) -> 1.7808 | I8: =STDEV(C8:G8) -> 0.051673978 | J8: =(I8/H8)*100 -> 2.9017283 | L8: fannkuch-redux | M8: C | N8: 2.9017283
A9: fannkuch-redux | B9: Go | C9: 6.813 | D9: 6.834 | E9: 6.884 | F9: 6.958 | G9: 6.958 | H9: =AVERAGE(C9:G9) -> 6.8894 | I9: =STDEV(C9:G9) -> 0.067725918 | J9: =(I9/H9)*100 -> 0.98304523 | L9: fannkuch-redux | M9: Go | N9: 0.98304523
A10: fannkuch-redux | B10: Python | C10: 285.672 | D10: 283.805 | E10: 282.058 | F10: 283.891 | G10: 282.432 | H10: =AVERAGE(C10:G10) -> 283.5716 | I10: =STDEV(C10:G10) -> 1.4280971 | J10: =(I10/H10)*100 -> 0.50361076 | L10: fannkuch-redux | M10: Python | N10: 0.50361076
A11: fannkuch-redux | B11: C CLBG | C11: 2.263 | D11: 2.262 | E11: 2.272 | F11: 2.248 | G11: 2.256 | H11: =AVERAGE(C11:G11) -> 2.2602 | I11: =STDEV(C11:G11) -> 0.0088994382 | J11: =(I11/H11)*100 -> 0.39374561 | L11: fannkuch-redux | M11: C CLBG | N11: 0.39374561
A12: fannkuch-redux | B12: Go CLBG | C12: 8.364 | D12: 8.382 | E12: 8.36 | F12: 8.402 | G12: 8.355 | H12: =AVERAGE(C12:G12) -> 8.3726 | I12: =STDEV(C12:G12) -> 0.019333908 | J12: =(I12/H12)*100 -> 0.23091881 | L12: fannkuch-redux | M12: Go CLBG | N12: 0.23091881
A13: fannkuch-redux | B13: Python CLBG | C13: 311.175 | D13: 311.17 | E13: 311.146 | F13: 311.232 | G13: 311.098 | H13: =AVERAGE(C13:G13) -> 311.1642 | I13: =STDEV(C13:G13) -> 0.048633322 | J13: =(I13/H13)*100 -> 0.015629472 | L13: fannkuch-redux | M13: Python CLBG | N13: 0.015629472
... A21: k-nucleotide | B21: Python CLBG | C21: 49.918 | D21: 47.493 | E21: 47.607 | F21: 46.982 | G21: 47.096 | H21: =AVERAGE(C21:G21) -> 47.8192 | I21: =STDEV(C21:G21) -> 1.2021147 | J21: =(I21/H21)*100 -> 2.5138745 | L21: k-nucleotide | M21: Python CLBG | N21: 2.5138745
A22: k-nucleotide | B22: C CLBG | C22: 3.775 | D22: 3.775 | E22: 3.789 | F22: 3.7 | G22: 3.764 | H22: 3.731 | I22: =STDEV(C22:G22) -> 0.035018567 | J22: =(I22/H22)*100 -> 0.93858393 | L22: k-nucleotide | M22: C CLBG | N22: 1.8045712
A23: k-nucleotide | B23: C | C23: 3.462 | D23: 3.504 | E23: 3.527 | F23: 3.571 | G23: 3.531 | H23: =AVERAGE(C23:G23) -> 3.519 | I23: =STDEV(C23:G23) -> 0.039956226 | J23: =(I23/H23)*100 -> 1.1354426 | L23: k-nucleotide | M23: C | N23: 1.1354426
A24: k-nucleotide | B24: Go | C24: 4.22 | D24: 4.337 | E24: 4.232 | F24: 4.24 | G24: 4.244 | H24: =AVERAGE(C24:G24) -> 4.2546 | I24: =STDEV(C24:G24) -> 0.046965945 | J24: =(I24/H24)*100 -> 1.1038863 | L24: k-nucleotide | M24: Go | N24: 1.1038863 | Q24: 3.775 | R24: {=TRANSPOSE(Q24:Q28)} -> 3.775 | S24: 3.789 | T24: 3.7 | U24: 3.764 | V24: 3.731
A25: k-nucleotide | B25: Go CLBG | C25: 7.589 | D25: 7.681 | E25: 7.665 | F25: 7.7 | G25: 7.577 | H25: =AVERAGE(C25:G25) -> 7.6424 | I25: =STDEV(C25:G25) -> 0.05578351 | J25: =(I25/H25)*100 -> 0.72992136 | L25: k-nucleotide | M25: Go CLBG | N25: 0.72992136 | Q25: 3.789
A26: mandelbrot | B26: Python | C26: 200.047 | D26: 203.772 | E26: 201.417 | F26: 203.161 | G26: 202.895 | H26: =AVERAGE(C26:G26) -> 202.2584 | I26: =STDEV(C26:G26) -> 1.5090705 | J26: =(I26/H26)*100 -> 0.74611018 | L26: mandelbrot | M26: Python | N26: 0.74611018 | Q26: 3.7
A27: mandelbrot | B27: C | C27: 1.656 | D27: 1.653 | E27: 1.64 | F27: 1.646 | G27: 1.637 | H27: =AVERAGE(C27:G27) -> 1.6464 | I27: =STDEV(C27:G27) -> 0.0081424812 | J27: =(I27/H27)*100 -> 0.49456275 | L27: mandelbrot | M27: C | N27: 0.49456275 | Q27: 3.764
A28: mandelbrot | B28: Go | C28: 3.324 | D28: 3.359 | E28: 3.339 | F28: 3.319 | G28: 3.333 | H28: =AVERAGE(C28:G28) -> 3.3348 | I28: =STDEV(C28:G28) -> 0.015594871 | J28: =(I28/H28)*100 -> 0.46764037 | L28: mandelbrot | M28: Go | N28: 0.46764037 | Q28: 3.731
A29: mandelbrot | B29: C CLBG | C29: 1.564 | D29: 1.552 | E29: 1.549 | F29: 1.551 | G29: 1.547 | H29: =AVERAGE(C29:G29) -> 1.5526 | I29: =STDEV(C29:G29) -> 0.0066558245 | J29: =(I29/H29)*100 -> 0.42868894 | L29: mandelbrot | M29: C CLBG | N29: 0.42868894
A30: mandelbrot | B30: Go CLBG | C30: 3.788 | D30: 3.78 | E30: 3.78 | F30: 3.779 | G30: 3.798 | H30: =AVERAGE(C30:G30) -> 3.785 | I30: =STDEV(C30:G30) -> 0.0081240384 | J30: =(I30/H30)*100 -> 0.21463774 | L30: mandelbrot | M30: Go CLBG | N30: 0.21463774
A31: mandelbrot | B31: Python CLBG | C31: 182.938 | D31: 182.933 | E31: 182.909 | F31: 182.995 | G31: 182.861 | H31: =AVERAGE(C31:G31) -> 182.9272 | I31: =STDEV(C31:G31) -> 0.048633322 | J31: =(I31/H31)*100 -> 0.026586162 | L31: mandelbrot | M31: Python CLBG | N31: 0.026586162
A32: n-body | B32: Go | C32: 3.873 | D32: 3.878 | E32: 3.907 | F32: 3.85 | G32: 3.927 | H32: =AVERAGE(C32:G32) -> 3.887 | I32: =STDEV(C32:G32) -> 0.030191058 | J32: =(I32/H32)*100 -> 0.77671876 | L32: n-body | M32: Go | N32: 0.77671876
A33: n-body | B33: C | C33: 1.688 | D33: 1.69 | E33: 1.698 | F33: 1.688 | G33: 1.713 | H33: =AVERAGE(C33:G33) -> 1.6954 | I33: =STDEV(C33:G33) -> 0.010667708 | J33: =(I33/H33)*100 -> 0.62921483 | L33: n-body | M33: C | N33: 0.62921483
A34: n-body | B34: Python | C34: 234.158 | D34: 232.787 | E34: 233.076 | F34: 234.296 | G34: 234.707 | H34: =AVERAGE(C34:G34) -> 233.8048 | I34: =STDEV(C34:G34) -> 0.82871268 | J34: =(I34/H34)*100 -> 0.35444639 | L34: n-body | M34: Python | N34: 0.35444639
A35: n-body | B35: C CLBG | C35: 2.21 | D35: 2.207 | E35: 2.209 | F35: 2.208 | G35: 2.203 | H35: =AVERAGE(C35:G35) -> 2.2074 | I35: =STDEV(C35:G35) -> 0.0027018512 | J35: =(I35/H35)*100 -> 0.12239971 | L35: n-body | M35: C CLBG | N35: 0.12239971
A36: n-body | B36: Go CLBG | C36: 6.385 | D36: 6.396 | E36: 6.393 | F36: 6.395 | G36: 6.39 | H36: =AVERAGE(C36:G36) -> 6.3918 | I36: =STDEV(C36:G36) -> 0.0044384682 | J36: =(I36/H36)*100 -> 0.069440036 | L36: n-body | M36: Go CLBG | N36: 0.069440036
A37: n-body | B37: Python CLBG | C37: 372.412 | D37: 372.407 | E37: 372.383 | F37: 372.469 | G37: 372.335 | H37: =AVERAGE(C37:G37) -> 372.4012 | I37: =STDEV(C37:G37) -> 0.048633322 | J37: =(I37/H37)*100 -> 0.013059389 | L37: n-body | M37: Python CLBG | N37: 0.013059389
A38: pi-digits | B38: Python CLBG | C38: 1.351 | D38: 1.381 | E38: 1.377 | F38: 1.355 | G38: 1.361 | H38: =AVERAGE(C38:G38) -> 1.365 | I38: =STDEV(C38:G38) -> 0.013341664 | J38: =(I38/H38)*100 -> 0.97741129 | L38: pi-digits | M38: Python CLBG | N38: 2.3300707
A39: pi-digits | B39: C | C39: 0.631 | D39: 0.652 | E39: 0.651 | F39: 0.653 | G39: 0.655 | H39: =AVERAGE(C39:G39) -> 0.6484 | I39: =STDEV(C39:G39) -> 0.0098386991 | J39: =(I39/H39)*100 -> 1.5173811 | L39: pi-digits | M39: C | N39: 1.5173811
A40: pi-digits | B40: Python | C40: 1.138 | D40: 1.16 | E40: 1.154 | F40: 1.141 | G40: 1.175 | H40: =AVERAGE(C40:G40) -> 1.1536 | I40: =STDEV(C40:G40) -> 0.015009997 | J40: =(I40/H40)*100 -> 1.301144 | L40: pi-digits | M40: Python | N40: 1.301144
... A61: spectral-norm | B61: Python CLBG | C61: 90.371 | D61: 90.366 | E61: 90.342 | F61: 90.428 | G61: 90.294 | H61: =AVERAGE(C61:G61) -> 90.3602 | I61: =STDEV(C61:G61) -> 0.048633322 | J61: =(I61/H61)*100 -> 0.053821618 | L61: spectral-norm | M61: Python CLBG | N61: 0.053821618

Sheet fasta
A1: PROMPT | B1: SEARCH TYPE | C1: AI TOOL | D1: P. L. | E1: RUNTIME | L1: OUTPUT COMMENT
E2: M1 | F2: M2 | G2: M3 | H2: M4 | I2: M5 | J2: AVG | K2: STD
A3: P1 | B3: Normal | C3: ChatGPT | D3: Python | E3: 108.361 | F3: 101.761 | G3: 114.28 | H3: 109.25 | I3: 118.561 | J3: =AVERAGE(E3:I3) -> 110.4426 | K3: =STDEV(E3:I3) -> 6.3592372 | M3: {=_xlfn.LET(_xlpm.lang, D3,_xlpm.tempo, J3,_xlpm.ref, _xlfn.XLOOKUP(_xlpm.lang, $D$44:$D$50, $J$44:$J$50, ""), IF(_xlpm.ref="", "Not Applicable", IF(_xlpm.tempo>_xlpm.ref, "Bigger", IF(_xlpm.tempo<_xlpm.ref, "Smaller", "Equal"))))} -> Bigger | Q3: MIN | R3: MAX | S3: PROMPT (MIN) | T3: SEARCH TYPE (MIN) | U3: PROMPT (MAX) | V3: SEARCH TYPE (MAX)
A4: P1 | B4: Normal | C4: Claude | D4: Python | E4: 177.026 | F4: 172.272 | G4: 156.527 | H4: 153.666 | I4: 157.89 | J4: =AVERAGE(E4:I4) -> 163.4762 | K4: =STDEV(E4:I4) -> 10.448687 | M4: {=_xlfn.LET(_xlpm.lang, D4,_xlpm.tempo, J4,_xlpm.ref, _xlfn.XLOOKUP(_xlpm.lang, $D$44:$D$50, $J$44:$J$50, ""), IF(_xlpm.ref="", "Not Applicable", IF(_xlpm.tempo>_xlpm.ref, "Bigger", IF(_xlpm.tempo<_xlpm.ref, "Smaller", "Equal"))))} -> Bigger | P4: C | Q4: =_xlfn.MINIFS($J$3:$J$43,$D$3:$D$43,"C") -> 12.2486 | R4: =_xlfn.MAXIFS($J$3:$J$43,$D$3:$D$43,"C") -> 21.3114 | S4: {=INDEX($A$3:$A$43,MATCH(1,($D$3:$D$43="C")*($J$3:$J$43=_xlfn.MINIFS($J$3:$J$43,$D$3:$D$43,"C")),0))} -> P2 | T4: {=INDEX($B$3:$B$43,MATCH(1,($D$3:$D$43="C")*($J$3:$J$43=_xlfn.MINIFS($J$3:$J$43,$D$3:$D$43,"C")),0))} -> Normal | U4: {=INDEX($A$3:$A$43,MATCH(1,($D$3:$D$43="C")*($J$3:$J$43=_xlfn.MAXIFS($J$3:$J$43,$D$3:$D$43,"C")),0))} -> P4 | V4: {=INDEX($B$3:$B$43,MATCH(1,($D$3:$D$43="C")*($J$3:$J$43=_xlfn.MAXIFS($J$3:$J$43,$D$3:$D$43,"C")),0))} -> TBR
A5: P1 | B5: Normal | C5: Copilot | D5: Python | E5: 13.008 | F5: 12.751 | G5: 12.5 | H5: 12.526 | I5: 12.822 | J5: =AVERAGE(E5:I5) -> 12.7214 | K5: =STDEV(E5:I5) -> 0.21232946 | M5: {=_xlfn.LET(_xlpm.lang, D5,_xlpm.tempo, J5,_xlpm.ref, _xlfn.XLOOKUP(_xlpm.lang, $D$44:$D$50, $J$44:$J$50, ""), IF(_xlpm.ref="", "Not Applicable", IF(_xlpm.tempo>_xlpm.ref, "Bigger", IF(_xlpm.tempo<_xlpm.ref, "Smaller", "Equal"))))} -> Smaller | P5: Go | Q5: =_xlfn.MINIFS($J$3:$J$43,$D$3:$D$43,"Go") -> 10.327 | R5: =_xlfn.MAXIFS($J$3:$J$43,$D$3:$D$43,"Go") -> 14.7356 | S5: {=INDEX($A$3:$A$43,MATCH(1,($D$3:$D$43="Go")*($J$3:$J$43=_xlfn.MINIFS($J$3:$J$43,$D$3:$D$43,"Go")),0))} -> P3 | T5: {=INDEX($B$3:$B$43,MATCH(1,($D$3:$D$43="Go")*($J$3:$J$43=_xlfn.MINIFS($J$3:$J$43,$D$3:$D$43,"Go")),0))} -> Normal | U5: {=INDEX($A$3:$A$43,MATCH(1,($D$3:$D$43="Go")*($J$3:$J$43=_xlfn.MAXIFS($J$3:$J$43,$D$3:$D$43,"Go")),0))} -> P4 | V5: {=INDEX($B$3:$B$43,MATCH(1,($D$3:$D$43="Go")*($J$3:$J$43=_xlfn.MAXIFS($J$3:$J$43,$D$3:$D$43,"Go")),0))} -> TBR
A6: P1 | B6: Normal | C6: DeepSeek | D6: Python | E6: 20.268 | F6: 19.774 | G6: 20.048 | H6: 19.933 | I6: 19.744 | J6: =AVERAGE(E6:I6) -> 19.9534 | K6: =STDEV(E6:I6) -> 0.21469234 | M6: {=_xlfn.LET(_xlpm.lang, D6,_xlpm.tempo, J6,_xlpm.ref, _xlfn.XLOOKUP(_xlpm.lang, $D$44:$D$50, $J$44:$J$50, ""), IF(_xlpm.ref="", "Not Applicable", IF(_xlpm.tempo>_xlpm.ref, "Bigger", IF(_xlpm.tempo<_xlpm.ref, "Smaller", "Equal"))))} -> Smaller | P6: Python | Q6: =_xlfn.MINIFS($J$3:$J$43,$D$3:$D$43,"Python") -> 11.6524 | R6: =_xlfn.MAXIFS($J$3:$J$43,$D$3:$D$43,"Python") -> 163.4762 | S6: {=INDEX($A$3:$A$43,MATCH(1,($D$3:$D$43="Python")*($J$3:$J$43=_xlfn.MINIFS($J$3:$J$43,$D$3:$D$43,"Python")),0))} -> P2 | T6: {=INDEX($B$3:$B$43,MATCH(1,($D$3:$D$43="Python")*($J$3:$J$43=_xlfn.MINIFS($J$3:$J$43,$D$3:$D$43,"Python")),0))} -> Normal | U6: {=INDEX($A$3:$A$43,MATCH(1,($D$3:$D$43="Python")*($J$3:$J$43=_xlfn.MAXIFS($J$3:$J$43,$D$3:$D$43,"Python")),0))} -> P1 | V6: {=INDEX($B$3:$B$43,MATCH(1,($D$3:$D$43="Python")*($J$3:$J$43=_xlfn.MAXIFS($J$3:$J$43,$D$3:$D$43,"Python")),0))} -> Normal
A7: P1 | B7: Normal | C7: Gemini | D7: Python | E7: 20.644 | F7: 20.786 | G7: 20.322 | H7: 17.74 | I7: 25.31 | J7: =AVERAGE(E7:I7) -> 20.9604 | K7: =STDEV(E7:I7) -> 2.7307543 | M7: {=_xlfn.LET(_xlpm.lang, D7,_xlpm.tempo, J7,_xlpm.ref, _xlfn.XLOOKUP(_xlpm.lang, $D$44:$D$50, $J$44:$J$50, ""), IF(_xlpm.ref="", "Not Applicable", IF(_xlpm.tempo>_xlpm.ref, "Bigger", IF(_xlpm.tempo<_xlpm.ref, "Smaller", "Equal"))))} -> Smaller
A8: P1 | B8: TBR | C8: ChatGPT | D8: Python | E8: 116.278 | F8: 121.321 | G8: 113.044 | H8: 111.799 | I8: 114.464 | J8: =AVERAGE(E8:I8) -> 115.3812 | K8: =STDEV(E8:I8) -> 3.7155548 | M8: {=_xlfn.LET(_xlpm.lang, D8,_xlpm.tempo, J8,_xlpm.ref, _xlfn.XLOOKUP(_xlpm.lang, $D$44:$D$50, $J$44:$J$50, ""), IF(_xlpm.ref="", "Not Applicable", IF(_xlpm.tempo>_xlpm.ref, "Bigger", IF(_xlpm.tempo<_xlpm.ref, "Smaller", "Equal"))))} -> Bigger | P8: =COUNTIF(M3:M43, "Smaller") -> 5 | Q8: =COUNTIFS($M$3:$M43, "Smaller", $D$3:$D43, "Python") -> 4
A9: P1 | B9: TBR | C9: Claude | D9: Python | E9: 163.079 | F9: 157.723 | G9: 152.318 | H9: 176.955 | I9: 157.833 | J9: =AVERAGE(E9:I9) -> 161.5816 | K9: =STDEV(E9:I9) -> 9.398653 | M9: {=_xlfn.LET(_xlpm.lang, D9,_xlpm.tempo, J9,_xlpm.ref, _xlfn.XLOOKUP(_xlpm.lang, $D$44:$D$50, $J$44:$J$50, ""), IF(_xlpm.ref="", "Not Applicable", IF(_xlpm.tempo>_xlpm.ref, "Bigger", IF(_xlpm.tempo<_xlpm.ref, "Smaller", "Equal"))))} -> Bigger
A10: P1 | B10: TBR | C10: Copilot | D10: Python | E10: Failed | F10: Failed | G10: Failed | H10: Failed | I10: Failed | J10: Failed | K10: Failed | L10: Compiled ok. Wrong output.
A11: P1 | B11: TBR | C11: DeepSeek | D11: Python | E11: 47.044 | F11: 48.275 | G11: 48.16 | H11: 47.292 | I11: 48.336 | J11: =AVERAGE(E11:I11) -> 47.8214 | K11: =STDEV(E11:I11) -> 0.60618298 | M11: {=_xlfn.LET(_xlpm.lang, D11,_xlpm.tempo, J11,_xlpm.ref, _xlfn.XLOOKUP(_xlpm.lang, $D$44:$D$50, $J$44:$J$50, ""), IF(_xlpm.ref="", "Not Applicable", IF(_xlpm.tempo>_xlpm.ref, "Bigger", IF(_xlpm.tempo<_xlpm.ref, "Smaller", "Equal"))))} -> Bigger
A12: P1 | B12: TBR | C12: Gemini | D12: Python | E12: 99.264 | F12: 99.834 | G12: 88.214 | H12: 100.958 | I12: 102.389 | J12: =AVERAGE(E12:I12) -> 98.1318 | K12: =STDEV(E12:I12) -> 5.6712714 | M12: {=_xlfn.LET(_xlpm.lang, D12,_xlpm.tempo, J12,_xlpm.ref, _xlfn.XLOOKUP(_xlpm.lang, $D$44:$D$50, $J$44:$J$50, ""), IF(_xlpm.ref="", "Not Applicable", IF(_xlpm.tempo>_xlpm.ref, "Bigger", IF(_xlpm.tempo<_xlpm.ref, "Smaller", "Equal"))))} -> Bigger
A13: P2 | B13: Normal | C13: ChatGPT | D13: Go | E13: 10.651 | F13: 11.02 | G13: 10.418 | H13: 10.91 | I13: 10.851 | J13: =AVERAGE(E13:I13) -> 10.77 | K13: =STDEV(E13:I13) -> 0.23807877 | M13: {=_xlfn.LET(_xlpm.lang, D13,_xlpm.tempo, J13,_xlpm.ref, _xlfn.XLOOKUP(_xlpm.lang, $D$44:$D$50, $J$44:$J$50, ""), IF(_xlpm.ref="", "Not Applicable", IF(_xlpm.tempo>_xlpm.ref, "Bigger", IF(_xlpm.tempo<_xlpm.ref, "Smaller", "Equal"))))} -> Bigger
A14: P2 | B14: Normal | C14: Claude | D14: C | E14: 12.322 | F14: 12.057 | G14: 12.869 | H14: 11.87 | I14: 12.125 | J14: =AVERAGE(E14:I14) -> 12.2486 | K14: =STDEV(E14:I14) -> 0.38262553 | M14: {=_xlfn.LET(_xlpm.lang, D14,_xlpm.tempo, J14,_xlpm.ref, _xlfn.XLOOKUP(_xlpm.lang, $D$44:$D$50, $J$44:$J$50, ""), IF(_xlpm.ref="", "Not Applicable", IF(_xlpm.tempo>_xlpm.ref, "Bigger", IF(_xlpm.tempo<_xlpm.ref, "Smaller", "Equal"))))} -> Bigger
A15: P2 | B15: Normal | C15: Copilot | D15: C | E15: 20.463 | F15: 19.996 | G15: 20.024 | H15: 20.592 | I15: 19.787 | J15: =AVERAGE(E15:I15) -> 20.1724 | K15: =STDEV(E15:I15) -> 0.33992102 | M15: {=_xlfn.LET(_xlpm.lang, D15,_xlpm.tempo, J15,_xlpm.ref, _xlfn.XLOOKUP(_xlpm.lang, $D$44:$D$50, $J$44:$J$50, ""), IF(_xlpm.ref="", "Not Applicable", IF(_xlpm.tempo>_xlpm.ref, "Bigger", IF(_xlpm.tempo<_xlpm.ref, "Smaller", "Equal"))))} -> Bigger
A16: P2 | B16: Normal | C16: DeepSeek | D16: Python | E16: 11.654 | F16: 11.756 | G16: 11.581 | H16: 11.491 | I16: 11.78 | J16: =AVERAGE(E16:I16) -> 11.6524 | K16: =STDEV(E16:I16) -> 0.12058731 | M16: {=_xlfn.LET(_xlpm.lang, D16,_xlpm.tempo, J16,_xlpm.ref, _xlfn.XLOOKUP(_xlpm.lang, $D$44:$D$50, $J$44:$J$50, ""), IF(_xlpm.ref="", "Not Applicable", IF(_xlpm.tempo>_xlpm.ref, "Bigger", IF(_xlpm.tempo<_xlpm.ref, "Smaller", "Equal"))))} -> Smaller
A17: P2 | B17: Normal | C17: Gemini | D17: C++ | E17: 8.298 | F17: 7.82 | G17: 7.645 | H17: 7.837 | I17: 8.117 | J17: =AVERAGE(E17:I17) -> 7.9434 | K17: =STDEV(E17:I17) -> 0.26051353 | M17: {=_xlfn.LET(_xlpm.lang, D17,_xlpm.tempo, J17,_xlpm.ref, _xlfn.XLOOKUP(_xlpm.lang, $D$44:$D$50, $J$44:$J$50, ""), IF(_xlpm.ref="", "Not Applicable", IF(_xlpm.tempo>_xlpm.ref, "Bigger", IF(_xlpm.tempo<_xlpm.ref, "Smaller", "Equal"))))} -> Smaller
A18: P2 | B18: TBR | C18: ChatGPT | D18: Rust | E18: 17.371 | F18: 17.839 | G18: 18.363 | H18: 18.26 | I18: 18.11 | J18: =AVERAGE(E18:I18) -> 17.9886 | K18: =STDEV(E18:I18) -> 0.397612 | M18: {=_xlfn.LET(_xlpm.lang, D18,_xlpm.tempo, J18,_xlpm.ref, _xlfn.XLOOKUP(_xlpm.lang, $D$44:$D$50, $J$44:$J$50, ""), IF(_xlpm.ref="", "Not Applicable", IF(_xlpm.tempo>_xlpm.ref, "Bigger", IF(_xlpm.tempo<_xlpm.ref, "Smaller", "Equal"))))} -> Not Applicable
A19: P2 | B19: TBR | C19: Claude | D19: Python | E19: 126.344 | F19: 127.349 | G19: 124.707 | H19: 125.111 | I19: 128.055 | J19: =AVERAGE(E19:I19) -> 126.3132 | K19: =STDEV(E19:I19) -> 1.4259086 | M19: {=_xlfn.LET(_xlpm.lang, D19,_xlpm.tempo, J19,_xlpm.ref, _xlfn.XLOOKUP(_xlpm.lang, $D$44:$D$50, $J$44:$J$50, ""), IF(_xlpm.ref="", "Not Applicable", IF(_xlpm.tempo>_xlpm.ref, "Bigger", IF(_xlpm.tempo<_xlpm.ref, "Smaller", "Equal"))))} -> Bigger
A20: P2 | B20: TBR | C20: Copilot | D20: Go | E20: Failed | F20: Failed | G20: Failed | H20: Failed | I20: Failed | J20: Failed | K20: Failed | L20: It did not compile.
A21: P2 | B21: TBR | C21: DeepSeek | D21: Python | E21: Failed | F21: Failed | G21: Failed | H21: Failed | I21: Failed | J21: Failed | K21: Failed | L21: Compiled ok. Wrong output.
A22: P2 | B22: TBR | C22: Gemini | D22: Python | E22: 78.846 | F22: 79.274 | G22: 77.898 | H22: 79.143 | I22: 79.788 | J22: =AVERAGE(E22:I22) -> 78.9898 | K22: =STDEV(E22:I22) -> 0.69894005 | M22: {=_xlfn.LET(_xlpm.lang, D22,_xlpm.tempo, J22,_xlpm.ref, _xlfn.XLOOKUP(_xlpm.lang, $D$44:$D$50, $J$44:$J$50, ""), IF(_xlpm.ref="", "Not Applicable", IF(_xlpm.tempo>_xlpm.ref, "Bigger", IF(_xlpm.tempo<_xlpm.ref, "Smaller", "Equal"))))} -> Bigger
A23: P3 | B23: Normal | C23: ChatGPT | D23: Go | E23: 10.296 | F23: 9.859 | G23: 10.735 | H23: 10.614 | I23: 10.131 | J23: =AVERAGE(E23:I23) -> 10.327 | K23: =STDEV(E23:I23) -> 0.35610181 | M23: {=_xlfn.LET(_xlpm.lang, D23,_xlpm.tempo, J23,_xlpm.ref, _xlfn.XLOOKUP(_xlpm.lang, $D$44:$D$50, $J$44:$J$50, ""), IF(_xlpm.ref="", "Not Applicable", IF(_xlpm.tempo>_xlpm.ref, "Bigger", IF(_xlpm.tempo<_xlpm.ref, "Smaller", "Equal"))))} -> Bigger
A24: P3 | B24: Normal | C24: Claude | D24: Python | E24: 116.931 | F24: 124.04 | G24: 120.32 | H24: 112.362 | I24: 133.96 | J24: =AVERAGE(E24:I24) -> 121.5226 | K24: =STDEV(E24:I24) -> 8.1772833 | M24: {=_xlfn.LET(_xlpm.lang, D24,_xlpm.tempo, J24,_xlpm.ref, _xlfn.XLOOKUP(_xlpm.lang, $D$44:$D$50, $J$44:$J$50, ""), IF(_xlpm.ref="", "Not Applicable", IF(_xlpm.tempo>_xlpm.ref, "Bigger", IF(_xlpm.tempo<_xlpm.ref, "Smaller", "Equal"))))} -> Bigger
A25: P3 | B25: Normal | C25: Copilot | D25: No Code | E25: Failed | F25: Failed | G25: Failed | H25: Failed | I25: Failed | J25: Failed | K25: Failed | L25: No Code
A26: P3 | B26: Normal | C26: DeepSeek | D26: Python | E26: Failed | F26: Failed | G26: Failed | H26: Failed | I26: Failed | J26: Failed | K26: Failed | L26: Compiled ok. Wrong output.
A27: P3 | B27: Normal | C27: DeepSeek | D27: C | E27: Failed | F27: Failed | G27: Failed | H27: Failed | I27: Failed | J27: Failed | K27: Failed | L27: Compiled ok. Wrong output.
A28: P3 | B28: Normal | C28: Gemini | D28: Python | E28: 148.884 | F28: 157.508 | G28: 143.589 | H28: 160.184 | I28: 165.963 | J28: =AVERAGE(E28:I28) -> 155.2256 | K28: =STDEV(E28:I28) -> 8.9542335 | M28: {=_xlfn.LET(_xlpm.lang, D28,_xlpm.tempo, J28,_xlpm.ref, _xlfn.XLOOKUP(_xlpm.lang, $D$44:$D$50, $J$44:$J$50, ""), IF(_xlpm.ref="", "Not Applicable", IF(_xlpm.tempo>_xlpm.ref, "Bigger", IF(_xlpm.tempo<_xlpm.ref, "Smaller", "Equal"))))} -> Bigger
A29: P3 | B29: TBR | C29: ChatGPT | D29: Rust | E29: Failed | F29: Failed | G29: Failed | H29: Failed | I29: Failed | J29: Failed | K29: Failed | L29: Compiled ok. Wrong output.
A30: P3 | B30: TBR | C30: Claude | D30: Python | E30: 112.891 | F30: 123.486 | G30: 118.635 | H30: 115.249 | I30: 123.974 | J30: =AVERAGE(E30:I30) -> 118.847 | K30: =STDEV(E30:I30) -> 4.9058876 | M30: {=_xlfn.LET(_xlpm.lang, D30,_xlpm.tempo, J30,_xlpm.ref, _xlfn.XLOOKUP(_xlpm.lang, $D$44:$D$50, $J$44:$J$50, ""), IF(_xlpm.ref="", "Not Applicable", IF(_xlpm.tempo>_xlpm.ref, "Bigger", IF(_xlpm.tempo<_xlpm.ref, "Smaller", "Equal"))))} -> Bigger
A31: P3 | B31: TBR | C31: Copilot | D31: Python | E31: Failed | F31: Failed | G31: Failed | H31: Failed | I31: Failed | J31: Failed | K31: Failed | L31: Compiled ok. Wrong output.
A32: P3 | B32: TBR | C32: DeepSeek | D32: Python | E32: 125.556 | F32: 110.999 | G32: 120.546 | H32: 112.615 | I32: 115.749 | J32: =AVERAGE(E32:I32) -> 117.093 | K32: =STDEV(E32:I32) -> 5.9695317 | M32: {=_xlfn.LET(_xlpm.lang, D32,_xlpm.tempo, J32,_xlpm.ref, _xlfn.XLOOKUP(_xlpm.lang, $D$44:$D$50, $J$44:$J$50, ""), IF(_xlpm.ref="", "Not Applicable", IF(_xlpm.tempo>_xlpm.ref, "Bigger", IF(_xlpm.tempo<_xlpm.ref, "Smaller", "Equal"))))} -> Bigger
A33: P3 | B33: TBR | C33: Gemini | D33: Python | E33: 117.163 | F33: 110.071 | G33: 127.659 | H33: 115.63 | I33: 117.807 | J33: =AVERAGE(E33:I33) -> 117.666 | K33: =STDEV(E33:I33) -> 6.3632197 | M33: {=_xlfn.LET(_xlpm.lang, D33,_xlpm.tempo, J33,_xlpm.ref, _xlfn.XLOOKUP(_xlpm.lang, $D$44:$D$50, $J$44:$J$50, ""), IF(_xlpm.ref="", "Not Applicable", IF(_xlpm.tempo>_xlpm.ref, "Bigger", IF(_xlpm.tempo<_xlpm.ref, "Smaller", "Equal"))))} -> Bigger
A34: P4 | B34: Normal | C34: ChatGPT | D34: Go | E34: 10.576 | F34: 10.608 | G34: 10.74 | H34: 9.727 | I34: 10.104 | J34: =AVERAGE(E34:I34) -> 10.351 | K34: =STDEV(E34:I34) -> 0.4237865 | M34: {=_xlfn.LET(_xlpm.lang, D34,_xlpm.tempo, J34,_xlpm.ref, _xlfn.XLOOKUP(_xlpm.lang, $D$44:$D$50, $J$44:$J$50, ""), IF(_xlpm.ref="", "Not Applicable", IF(_xlpm.tempo>_xlpm.ref, "Bigger", IF(_xlpm.tempo<_xlpm.ref, "Smaller", "Equal"))))} -> Bigger
A35: P4 | B35: Normal | C35: Claude | D35: Python | E35: 136.646 | F35: 147.486 | G35: 118.635 | H35: 115.249 | I35: 153.974 | J35: =AVERAGE(E35:I35) -> 134.398 | K35: =STDEV(E35:I35) -> 17.137134 | M35: {=_xlfn.LET(_xlpm.lang, D35,_xlpm.tempo, J35,_xlpm.ref, _xlfn.XLOOKUP(_xlpm.lang, $D$44:$D$50, $J$44:$J$50, ""), IF(_xlpm.ref="", "Not Applicable", IF(_xlpm.tempo>_xlpm.ref, "Bigger", IF(_xlpm.tempo<_xlpm.ref, "Smaller", "Equal"))))} -> Bigger
A36: P4 | B36: Normal | C36: Copilot | D36: Java | E36: 133.075 | F36: 125.517 | G36: 127.074 | H36: 125.512 | I36: 131.138 | J36: =AVERAGE(E36:I36) -> 128.4632 | K36: =STDEV(E36:I36) -> 3.4548085 | M36: {=_xlfn.LET(_xlpm.lang, D36,_xlpm.tempo, J36,_xlpm.ref, _xlfn.XLOOKUP(_xlpm.lang, $D$44:$D$50, $J$44:$J$50, ""), IF(_xlpm.ref="", "Not Applicable", IF(_xlpm.tempo>_xlpm.ref, "Bigger", IF(_xlpm.tempo<_xlpm.ref, "Smaller", "Equal"))))} -> Not Applicable
A37: P4 | B37: Normal | C37: DeepSeek | D37: Python | E37: 121.161 | F37: 120.826 | G37: 126.104 | H37: 142.158 | I37: 124.367 | J37: =AVERAGE(E37:I37) -> 126.9232 | K37: =STDEV(E37:I37) -> 8.7989087 | M37: {=_xlfn.LET(_xlpm.lang, D37,_xlpm.tempo, J37,_xlpm.ref, _xlfn.XLOOKUP(_xlpm.lang, $D$44:$D$50, $J$44:$J$50, ""), IF(_xlpm.ref="", "Not Applicable", IF(_xlpm.tempo>_xlpm.ref, "Bigger", IF(_xlpm.tempo<_xlpm.ref, "Smaller", "Equal"))))} -> Bigger
A38: P4 | B38: Normal | C38: Gemini | D38: Python | E38: Failed | F38: Failed | G38: Failed | H38: Failed | I38: Failed | J38: Failed | K38: Failed | L38: Compiled ok. Wrong output.
A39: P4 | B39: TBR | C39: ChatGPT | D39: Go | E39: 14.578 | F39: 14.883 | G39: 14.865 | H39: 14.873 | I39: 14.479 | J39: =AVERAGE(E39:I39) -> 14.7356 | K39: =STDEV(E39:I39) -> 0.19237411 | M39: {=_xlfn.LET(_xlpm.lang, D39,_xlpm.tempo, J39,_xlpm.ref, _xlfn.XLOOKUP(_xlpm.lang, $D$44:$D$50, $J$44:$J$50, ""), IF(_xlpm.ref="", "Not Applicable", IF(_xlpm.tempo>_xlpm.ref, "Bigger", IF(_xlpm.tempo<_xlpm.ref, "Smaller", "Equal"))))} -> Bigger
A40: P4 | B40: TBR | C40: Claude | D40: C | E40: 21.728 | F40: 21.895 | G40: 21.71 | H40: 20.384 | I40: 20.84 | J40: =AVERAGE(E40:I40) -> 21.3114 | K40: =STDEV(E40:I40) -> 0.66244154 | M40: {=_xlfn.LET(_xlpm.lang, D40,_xlpm.tempo, J40,_xlpm.ref, _xlfn.XLOOKUP(_xlpm.lang, $D$44:$D$50, $J$44:$J$50, ""), IF(_xlpm.ref="", "Not Applicable", IF(_xlpm.tempo>_xlpm.ref, "Bigger", IF(_xlpm.tempo<_xlpm.ref, "Smaller", "Equal"))))} -> Bigger
...

Sheet binary-trees
A1: PROMPT | B1: SEARCH TYPE | C1: AI TOOL | D1: P. L. | E1: RUNTIME | L1: OUTPUT COMMENT
E2: M1 | F2: M2 | G2: M3 | H2: M4 | I2: M5 | J2: AVG | K2: STD
A3: P1 | B3: Normal | C3: ChatGPT | D3: C | E3: 20.344 | F3: 20.712 | G3: 20.47 | H3: 20.243 | I3: 20.35 | J3: =AVERAGE(E3:I3) -> 20.4238 | K3: =STDEV(E3:I3) -> 0.18006721 | M3: {=_xlfn.LET(_xlpm.lang, D3,_xlpm.tempo, J3,_xlpm.ref, _xlfn.XLOOKUP(_xlpm.lang, $D$74:$D$80, $J$74:$J$80, ""), IF(_xlpm.ref="", "Not Applicable", IF(_xlpm.tempo>_xlpm.ref, "Bigger", IF(_xlpm.tempo<_xlpm.ref, "Smaller", "Equal"))))} -> Bigger | P3: MIN | Q3: MAX | R3: PROMPT (MIN) | S3: SEARCH TYPE (MIN) | T3: PROMPT (MAX) | U3: SEARCH TYPE (MAX)
A4: P1 | B4: Normal | C4: Claude | D4: C++ | E4: 0.384 | F4: 0.393 | G4: 0.383 | H4: 0.394 | I4: 0.388 | J4: =AVERAGE(E4:I4) -> 0.3884 | K4: =STDEV(E4:I4) -> 0.0050299105 | M4: {=_xlfn.LET(_xlpm.lang, D4,_xlpm.tempo, J4,_xlpm.ref, _xlfn.XLOOKUP(_xlpm.lang, $D$74:$D$80, $J$74:$J$80, ""), IF(_xlpm.ref="", "Not Applicable", IF(_xlpm.tempo>_xlpm.ref, "Bigger", IF(_xlpm.tempo<_xlpm.ref, "Smaller", "Equal"))))} -> Smaller | O4: C | P4: =_xlfn.MINIFS($J$3:$J$73,$D$3:$D$73,"C") -> 0.0876 | Q4: =_xlfn.MAXIFS($J$3:$J$73,$D$3:$D$73,"C") -> 20.4238 | R4: {=INDEX($A$3:$A$73,MATCH(1,($D$3:$D$73="C")*($J$3:$J$73=_xlfn.MINIFS($J$3:$J$73,$D$3:$D$73,"C")),0))} -> P2 | S4: {=INDEX($B$3:$B$73,MATCH(1,($D$3:$D$73="C")*($J$3:$J$73=_xlfn.MINIFS($J$3:$J$73,$D$3:$D$73,"C")),0))} -> Normal | T4: {=INDEX($A$3:$A$73,MATCH(1,($D$3:$D$73="C")*($J$3:$J$73=_xlfn.MAXIFS($J$3:$J$73,$D$3:$D$73,"C")),0))} -> P1 | U4: {=INDEX($B$3:$B$73,MATCH(1,($D$3:$D$73="C")*($J$3:$J$73=_xlfn.MAXIFS($J$3:$J$73,$D$3:$D$73,"C")),0))} -> Normal
A5: P1 | B5: Normal | C5: Claude | D5: Java | E5: 0.196 | F5: 0.343 | G5: 0.357 | H5: 0.368 | I5: 0.374 | J5: =AVERAGE(E5:I5) -> 0.3276 | K5: =STDEV(E5:I5) -> 0.074507047 | M5: {=_xlfn.LET(_xlpm.lang, D5,_xlpm.tempo, J5,_xlpm.ref, _xlfn.XLOOKUP(_xlpm.lang, $D$74:$D$80, $J$74:$J$80, ""), IF(_xlpm.ref="", "Not Applicable", IF(_xlpm.tempo>_xlpm.ref, "Bigger", IF(_xlpm.tempo<_xlpm.ref, "Smaller", "Equal"))))} -> Not Applicable | O5: Go | P5: =_xlfn.MINIFS($J$3:$J$73,$D$3:$D$73,"Go") -> 0.0524 | Q5: =_xlfn.MAXIFS($J$3:$J$73,$D$3:$D$73,"Go") -> 25.933 | R5: {=INDEX($A$3:$A$73,MATCH(1,($D$3:$D$73="Go")*($J$3:$J$73=_xlfn.MINIFS($J$3:$J$73,$D$3:$D$73,"Go")),0))} -> P2 | S5: {=INDEX($B$3:$B$73,MATCH(1,($D$3:$D$73="Go")*($J$3:$J$73=_xlfn.MINIFS($J$3:$J$73,$D$3:$D$73,"Go")),0))} -> TBR | T5: {=INDEX($A$3:$A$73,MATCH(1,($D$3:$D$73="Go")*($J$3:$J$73=_xlfn.MAXIFS($J$3:$J$73,$D$3:$D$73,"Go")),0))} -> P3 | U5: {=INDEX($B$3:$B$73,MATCH(1,($D$3:$D$73="Go")*($J$3:$J$73=_xlfn.MAXIFS($J$3:$J$73,$D$3:$D$73,"Go")),0))} -> Normal
A6: P1 | B6: Normal | C6: Claude | D6: Python | E6: 5.038 | F6: 5.094 | G6: 5.15 | H6: 5.073 | I6: 5.081 | J6: =AVERAGE(E6:I6) -> 5.0872 | K6: =STDEV(E6:I6) -> 0.040776219 | M6: {=_xlfn.LET(_xlpm.lang, D6,_xlpm.tempo, J6,_xlpm.ref, _xlfn.XLOOKUP(_xlpm.lang, $D$74:$D$80, $J$74:$J$80, ""), IF(_xlpm.ref="", "Not Applicable", IF(_xlpm.tempo>_xlpm.ref, "Bigger", IF(_xlpm.tempo<_xlpm.ref, "Smaller", "Equal"))))} -> Smaller | O6: Python | P6: =_xlfn.MINIFS($J$3:$J$73,$D$3:$D$73,"Python") -> 0.792 | Q6: =_xlfn.MAXIFS($J$3:$J$73,$D$3:$D$73,"Python") -> 441.4248 | R6: {=INDEX($A$3:$A$73,MATCH(1,($D$3:$D$73="Python")*($J$3:$J$73=_xlfn.MINIFS($J$3:$J$73,$D$3:$D$73,"Python")),0))} -> P1 | S6: {=INDEX($B$3:$B$73,MATCH(1,($D$3:$D$73="Python")*($J$3:$J$73=_xlfn.MINIFS($J$3:$J$73,$D$3:$D$73,"Python")),0))} -> Normal | T6: {=INDEX($A$3:$A$73,MATCH(1,($D$3:$D$73="Python")*($J$3:$J$73=_xlfn.MAXIFS($J$3:$J$73,$D$3:$D$73,"Python")),0))} -> P3 | U6: {=INDEX($B$3:$B$73,MATCH(1,($D$3:$D$73="Python")*($J$3:$J$73=_xlfn.MAXIFS($J$3:$J$73,$D$3:$D$73,"Python")),0))} -> Normal
A7: P1 | B7: Normal | C7: Claude | D7: C# | E7: 0.635 | F7: 0.626 | G7: 0.654 | H7: 0.611 | I7: 0.639 | J7: =AVERAGE(E7:I7) -> 0.633 | K7: =STDEV(E7:I7) -> 0.015921683 | M7: {=_xlfn.LET(_xlpm.lang, D7,_xlpm.tempo, J7,_xlpm.ref, _xlfn.XLOOKUP(_xlpm.lang, $D$74:$D$80, $J$74:$J$80, ""), IF(_xlpm.ref="", "Not Applicable", IF(_xlpm.tempo>_xlpm.ref, "Bigger", IF(_xlpm.tempo<_xlpm.ref, "Smaller", "Equal"))))} -> Not Applicable
A8: P1 | B8: Normal | C8: Copilot | D8: C | E8: Failed | F8: Failed | G8: Failed | H8: Failed | I8: Failed | J8: Failed | K8: Failed | L8: It did not compile. | O8: =COUNTIF(M3:M73, "Smaller") -> 14 | P8: =COUNTIFS($M$3:$M73, "Smaller", $D$3:$D73, "Python") -> 5
A9: P1 | B9: Normal | C9: Copilot | D9: Java | E9: Failed | F9: Failed | G9: Failed | H9: Failed | I9: Failed | J9: Failed | K9: Failed | L9: It did not compile.
A10: P1 | B10: Normal | C10: DeepSeek | D10: Java | E10: Failed | F10: Failed | G10: Failed | H10: Failed | I10: Failed | J10: Failed | K10: Failed | L10: It did not compile.
A11: P1 | B11: Normal | C11: DeepSeek | D11: C++ | E11: 0.552 | F11: 0.556 | G11: 0.572 | H11: 0.576 | I11: 0.549 | J11: =AVERAGE(E11:I11) -> 0.561 | K11: =STDEV(E11:I11) -> 0.012206556 | M11: {=_xlfn.LET(_xlpm.lang, D11,_xlpm.tempo, J11,_xlpm.ref, _xlfn.XLOOKUP(_xlpm.lang, $D$74:$D$80, $J$74:$J$80, ""), IF(_xlpm.ref="", "Not Applicable", IF(_xlpm.tempo>_xlpm.ref, "Bigger", IF(_xlpm.tempo<_xlpm.ref, "Smaller", "Equal"))))} -> Smaller
A12: P1 | B12: Normal | C12: DeepSeek | D12: Python | E12: 0.787 | F12: 0.803 | G12: 0.79 | H12: 0.791 | I12: 0.789 | J12: =AVERAGE(E12:I12) -> 0.792 | K12: =STDEV(E12:I12) -> 0.0063245553 | M12: {=_xlfn.LET(_xlpm.lang, D12,_xlpm.tempo, J12,_xlpm.ref, _xlfn.XLOOKUP(_xlpm.lang, $D$74:$D$80, $J$74:$J$80, ""), IF(_xlpm.ref="", "Not Applicable", IF(_xlpm.tempo>_xlpm.ref, "Bigger", IF(_xlpm.tempo<_xlpm.ref, "Smaller", "Equal"))))} -> Smaller
A13: P1 | B13: Normal | C13: Gemini | D13: Java | E13: 0.363 | F13: 0.362 | G13: 0.329 | H13: 0.364 | I13: 0.362 | J13: =AVERAGE(E13:I13) -> 0.356 | K13: =STDEV(E13:I13) -> 0.015116216 | M13: {=_xlfn.LET(_xlpm.lang, D13,_xlpm.tempo, J13,_xlpm.ref, _xlfn.XLOOKUP(_xlpm.lang, $D$74:$D$80, $J$74:$J$80, ""), IF(_xlpm.ref="", "Not Applicable", IF(_xlpm.tempo>_xlpm.ref, "Bigger", IF(_xlpm.tempo<_xlpm.ref, "Smaller", "Equal"))))} -> Not Applicable
A14: P1 | B14: TBR | C14: ChatGPT | D14: C | E14: 6.862 | F14: 6.974 | G14: 7.056 | H14: 6.868 | I14: 6.892 | J14: =AVERAGE(E14:I14) -> 6.9304 | K14: =STDEV(E14:I14) -> 0.083251426 | M14: {=_xlfn.LET(_xlpm.lang, D14,_xlpm.tempo, J14,_xlpm.ref, _xlfn.XLOOKUP(_xlpm.lang, $D$74:$D$80, $J$74:$J$80, ""), IF(_xlpm.ref="", "Not Applicable", IF(_xlpm.tempo>_xlpm.ref, "Bigger", IF(_xlpm.tempo<_xlpm.ref, "Smaller", "Equal"))))} -> Bigger
A15: P1 | B15: TBR | C15: Claude | D15: C | E15: 0.259 | F15: 0.249 | G15: 0.248 | H15: 0.254 | I15: 0.256 | J15: =AVERAGE(E15:I15) -> 0.2532 | K15: =STDEV(E15:I15) -> 0.0046583259 | M15: {=_xlfn.LET(_xlpm.lang, D15,_xlpm.tempo, J15,_xlpm.ref, _xlfn.XLOOKUP(_xlpm.lang, $D$74:$D$80, $J$74:$J$80, ""), IF(_xlpm.ref="", "Not Applicable", IF(_xlpm.tempo>_xlpm.ref, "Bigger", IF(_xlpm.tempo<_xlpm.ref, "Smaller", "Equal"))))} -> Smaller
A16: P1 | B16: TBR | C16: Claude | D16: Python | E16: 53.916 | F16: 55.11 | G16: 54.466 | H16: 54.142 | I16: 54.918 | J16: =AVERAGE(E16:I16) -> 54.5104 | K16: =STDEV(E16:I16) -> 0.5041476 | M16: {=_xlfn.LET(_xlpm.lang, D16,_xlpm.tempo, J16,_xlpm.ref, _xlfn.XLOOKUP(_xlpm.lang, $D$74:$D$80, $J$74:$J$80, ""), IF(_xlpm.ref="", "Not Applicable", IF(_xlpm.tempo>_xlpm.ref, "Bigger", IF(_xlpm.tempo<_xlpm.ref, "Smaller", "Equal"))))} -> Bigger
A17: P1 | B17: TBR | C17: Claude | D17: Java | E17: 0.701 | F17: 0.733 | G17: 0.74 | H17: 0.727 | I17: 0.749 | J17: =AVERAGE(E17:I17) -> 0.73 | K17: =STDEV(E17:I17) -> 0.018165902 | M17: {=_xlfn.LET(_xlpm.lang, D17,_xlpm.tempo, J17,_xlpm.ref, _xlfn.XLOOKUP(_xlpm.lang, $D$74:$D$80, $J$74:$J$80, ""), IF(_xlpm.ref="", "Not Applicable", IF(_xlpm.tempo>_xlpm.ref, "Bigger", IF(_xlpm.tempo<_xlpm.ref, "Smaller", "Equal"))))} -> Not Applicable
A18: P1 | B18: TBR | C18: Copilot | D18: Java | E18: Failed | F18: Failed | G18: Failed | H18: Failed | I18: Failed | J18: Failed | K18: Failed | L18: It did not compile.
A19: P1 | B19: TBR | C19: Copilot | D19: Go | E19: Failed | F19: Failed | G19: Failed | H19: Failed | I19: Failed | J19: Failed | K19: Failed | L19: It did not compile.
A20: P1 | B20: TBR | C20: DeepSeek | D20: C | E20: Failed | F20: Failed | G20: Failed | H20: Failed | I20: Failed | J20: Failed | K20: Failed | L20: It did not compile.
A21: P1 | B21: TBR | C21: DeepSeek | D21: Java | E21: Failed | F21: Failed | G21: Failed | H21: Failed | I21: Failed | J21: Failed | K21: Failed | L21: It did not compile.
A22: P1 | B22: TBR | C22: DeepSeek | D22: Python | E22: Failed | F22: Failed | G22: Failed | H22: Failed | I22: Failed | J22: Failed | K22: Failed | L22: Compiled ok. Wrong output.
A23: P1 | B23: TBR | C23: DeepSeek | D23: Go | E23: Failed | F23: Failed | G23: Failed | H23: Failed | I23: Failed | J23: Failed | K23: Failed | L23: It did not compile.
A24: P1 | B24: TBR | C24: Gemini | D24: Python | E24: 6.9 | F24: 6.784 | G24: 6.672 | H24: 6.698 | I24: 6.761 | J24: =AVERAGE(E24:I24) -> 6.763 | K24: =STDEV(E24:I24) -> 0.089050547 | M24: {=_xlfn.LET(_xlpm.lang, D24,_xlpm.tempo, J24,_xlpm.ref, _xlfn.XLOOKUP(_xlpm.lang, $D$74:$D$80, $J$74:$J$80, ""), IF(_xlpm.ref="", "Not Applicable", IF(_xlpm.tempo>_xlpm.ref, "Bigger", IF(_xlpm.tempo<_xlpm.ref, "Smaller", "Equal"))))} -> Smaller
A25: P2 | B25: Normal | C25: ChatGPT | D25: C | E25: Failed | F25: Failed | G25: Failed | H25: Failed | I25: Failed | J25: Failed | K25: Failed | L25: Compiled ok. Wrong output.
A26: P2 | B26: Normal | C26: Claude | D26: C++ | E26: 0.515 | F26: 0.527 | G26: 0.526 | H26: 0.509 | I26: 0.52 | J26: =AVERAGE(E26:I26) -> 0.5194 | K26: =STDEV(E26:I26) -> 0.0075696763 | M26: {=_xlfn.LET(_xlpm.lang, D26,_xlpm.tempo, J26,_xlpm.ref, _xlfn.XLOOKUP(_xlpm.lang, $D$74:$D$80, $J$74:$J$80, ""), IF(_xlpm.ref="", "Not Applicable", IF(_xlpm.tempo>_xlpm.ref, "Bigger", IF(_xlpm.tempo<_xlpm.ref, "Smaller", "Equal"))))} -> Smaller
A27: P2 | B27: Normal | C27: Claude | D27: Python | E27: 4.869 | F27: 4.817 | G27: 4.863 | H27: 4.853 | I27: 4.866 | J27: =AVERAGE(E27:I27) -> 4.8536 | K27: =STDEV(E27:I27) -> 0.02132604 | M27: {=_xlfn.LET(_xlpm.lang, D27,_xlpm.tempo, J27,_xlpm.ref, _xlfn.XLOOKUP(_xlpm.lang, $D$74:$D$80, $J$74:$J$80, ""), IF(_xlpm.ref="", "Not Applicable", IF(_xlpm.tempo>_xlpm.ref, "Bigger", IF(_xlpm.tempo<_xlpm.ref, "Smaller", "Equal"))))} -> Smaller
A28: P2 | B28: Normal | C28: Copilot | D28: C | E28: 0.088 | F28: 0.087 | G28: 0.087 | H28: 0.088 | I28: 0.088 | J28: =AVERAGE(E28:I28) -> 0.0876 | K28: =STDEV(E28:I28) -> 0.00054772256 | M28: {=_xlfn.LET(_xlpm.lang, D28,_xlpm.tempo, J28,_xlpm.ref, _xlfn.XLOOKUP(_xlpm.lang, $D$74:$D$80, $J$74:$J$80, ""), IF(_xlpm.ref="", "Not Applicable", IF(_xlpm.tempo>_xlpm.ref, "Bigger", IF(_xlpm.tempo<_xlpm.ref, "Smaller", "Equal"))))} -> Smaller
A29: P2 | B29: Normal | C29: DeepSeek | D29: C++ | E29: Failed | F29: Failed | G29: Failed | H29: Failed | I29: Failed | J29: Failed | K29: Failed | L29: It did not compile.
A30: P2 | B30: Normal | C30: Gemini | D30: Java | E30: Failed | F30: Failed | G30: Failed | H30: Failed | I30: Failed | J30: Failed | K30: Failed | L30: It did not compile.
A31: P2 | B31: TBR | C31: ChatGPT | D31: Go | E31: 0.054 | F31: 0.042 | G31: 0.057 | H31: 0.055 | I31: 0.054 | J31: =AVERAGE(E31:I31) -> 0.0524 | K31: =STDEV(E31:I31) -> 0.0059413803 | M31: {=_xlfn.LET(_xlpm.lang, D31,_xlpm.tempo, J31,_xlpm.ref, _xlfn.XLOOKUP(_xlpm.lang, $D$74:$D$80, $J$74:$J$80, ""), IF(_xlpm.ref="", "Not Applicable", IF(_xlpm.tempo>_xlpm.ref, "Bigger", IF(_xlpm.tempo<_xlpm.ref, "Smaller", "Equal"))))} -> Smaller
A32: P2 | B32: TBR | C32: Claude | D32: C | E32: 0.3984 | F32: 0.398 | G32: 0.396 | H32: 0.401 | I32: 0.397 | J32: =AVERAGE(E32:I32) -> 0.39808 | K32: =STDEV(E32:I32) -> 0.0018793616 | M32: {=_xlfn.LET(_xlpm.lang, D32,_xlpm.tempo, J32,_xlpm.ref, _xlfn.XLOOKUP(_xlpm.lang, $D$74:$D$80, $J$74:$J$80, ""), IF(_xlpm.ref="", "Not Applicable", IF(_xlpm.tempo>_xlpm.ref, "Bigger", IF(_xlpm.tempo<_xlpm.ref, "Smaller", "Equal"))))} -> Smaller
A33: P2 | B33: TBR | C33: Claude | D33: Python | E33: 3.29 | F33: 3.336 | G33: 3.301 | H33: 3.326 | I33: 3.321 | J33: =AVERAGE(E33:I33) -> 3.3148 | K33: =STDEV(E33:I33) -> 0.018833481 | M33: {=_xlfn.LET(_xlpm.lang, D33,_xlpm.tempo, J33,_xlpm.ref, _xlfn.XLOOKUP(_xlpm.lang, $D$74:$D$80, $J$74:$J$80, ""), IF(_xlpm.ref="", "Not Applicable", IF(_xlpm.tempo>_xlpm.ref, "Bigger", IF(_xlpm.tempo<_xlpm.ref, "Smaller", "Equal"))))} -> Smaller
A34: P2 | B34: TBR | C34: Copilot | D34: No Code | E34: Failed | F34: Failed | G34: Failed | H34: Failed | I34: Failed | J34: Failed | K34: Failed | L34: No Code
A35: P2 | B35: TBR | C35: DeepSeek | D35: C++ | E35: 0.869 | F35: 0.779 | G35: 0.708 | H35: 0.548 | I35: 0.539 | J35: =AVERAGE(E35:I35) -> 0.6886 | K35: =STDEV(E35:I35) -> 0.14425776 | M35: {=_xlfn.LET(_xlpm.lang, D35,_xlpm.tempo, J35,_xlpm.ref, _xlfn.XLOOKUP(_xlpm.lang, $D$74:$D$80, $J$74:$J$80, ""), IF(_xlpm.ref="", "Not Applicable", IF(_xlpm.tempo>_xlpm.ref, "Bigger", IF(_xlpm.tempo<_xlpm.ref, "Smaller", "Equal"))))} -> Smaller
A36: P2 | B36: TBR | C36: Gemini | D36: C++ | E36: Failed | F36: Failed | G36: Failed | H36: Failed | I36: Failed | J36: Failed | K36: Failed | L36: It did not compile.
A37: P3 | B37: Normal | C37: ChatGPT | D37: Go | E37: 25.722 | F37: 25.721 | G37: 26.037 | H37: 25.881 | I37: 26.304 | J37: =AVERAGE(E37:I37) -> 25.933 | K37: =STDEV(E37:I37) -> 0.24526822 | M37: {=_xlfn.LET(_xlpm.lang, D37,_xlpm.tempo, J37,_xlpm.ref, _xlfn.XLOOKUP(_xlpm.lang, $D$74:$D$80, $J$74:$J$80, ""), IF(_xlpm.ref="", "Not Applicable", IF(_xlpm.tempo>_xlpm.ref, "Bigger", IF(_xlpm.tempo<_xlpm.ref, "Smaller", "Equal"))))} -> Bigger
A38: P3 | B38: Normal | C38: Claude | D38: Python | E38: 447.588 | F38: 445.776 | G38: 422.557 | H38: 444.292 | I38: 446.911 | J38: =AVERAGE(E38:I38) -> 441.4248 | K38: =STDEV(E38:I38) -> 10.6211 | M38: {=_xlfn.LET(_xlpm.lang, D38,_xlpm.tempo, J38,_xlpm.ref, _xlfn.XLOOKUP(_xlpm.lang, $D$74:$D$80, $J$74:$J$80, ""), IF(_xlpm.ref="", "Not Applicable", IF(_xlpm.tempo>_xlpm.ref, "Bigger", IF(_xlpm.tempo<_xlpm.ref, "Smaller", "Equal"))))} -> Bigger
A39: P3 | B39: Normal | C39: Copilot | D39: No Code | E39: Failed | F39: Failed | G39: Failed | H39: Failed | I39: Failed | J39: Failed | K39: Failed | L39: No Code
A40: P3 | B40: Normal | C40: DeepSeek | D40: Python | E40: Failed | F40: Failed | G40: Failed | H40: Failed | I40: Failed | J40: Failed | K40: Failed | L40: Compiled ok. Wrong output.
...

Sheet fannkuch-redux
A1: PROMPT | B1: SEARCH TYPE | C1: AI TOOL | D1: P. L. | E1: RUNTIME | L1: OUTPUT COMMENT
E2: M1 | F2: M2 | G2: M3 | H2: M4 | I2: M5 | J2: AVG | K2: STD
A3: P1 | B3: Normal | C3: ChatGPT | D3: C | E3: Failed | F3: Failed | G3: Failed | H3: Failed | I3: Failed | J3: Failed | K3: Failed | L3: Compiled ok. Wrong output. | P3: MIN | Q3: MAX | R3: PROMPT (MIN) | S3: SEARCH TYPE (MIN) | T3: PROMPT (MAX) | U3: SEARCH TYPE (MAX)
